Workbook
Name Lista_Colores1: _xlfn.ANCHORARRAY(Aux!$D$4)
Name Lista_Colores10: _xlfn.ANCHORARRAY(Aux!$D$125)
Name Lista_Colores11: _xlfn.ANCHORARRAY(Aux!$D$138)
Name Lista_Colores12: _xlfn.ANCHORARRAY(Aux!$D$151)
Name Lista_Colores13: _xlfn.ANCHORARRAY(Aux!$D$164)
Name Lista_Colores14: _xlfn.ANCHORARRAY(Aux!$D$177)
Name Lista_Colores15: _xlfn.ANCHORARRAY(Aux!$D$190)
Name Lista_Colores16: _xlfn.ANCHORARRAY(Aux!$D$203)
Name Lista_Colores17: _xlfn.ANCHORARRAY(Aux!$D$216)
Name Lista_Colores18: _xlfn.ANCHORARRAY(Aux!$D$229)
Name Lista_Colores19: _xlfn.ANCHORARRAY(Aux!$D$242)
Name Lista_Colores2: _xlfn.ANCHORARRAY(Aux!$D$17)
Name Lista_Colores20: _xlfn.ANCHORARRAY(Aux!$D$255)
Name Lista_Colores3: _xlfn.ANCHORARRAY(Aux!$D$31)
Name Lista_Colores4: _xlfn.ANCHORARRAY(Aux!$D$45)
Name Lista_Colores5: _xlfn.ANCHORARRAY(Aux!$D$59)
Name Lista_Colores6: _xlfn.ANCHORARRAY(Aux!$D$72)
Name Lista_Colores7: _xlfn.ANCHORARRAY(Aux!$D$85)
Name Lista_Colores8: _xlfn.ANCHORARRAY(Aux!$D$98)
Name Lista_Colores9: _xlfn.ANCHORARRAY(Aux!$D$112)
Name Lista_Estilos1: _xlfn.ANCHORARRAY(Aux!$H$4)
Name Lista_Estilos10: _xlfn.ANCHORARRAY(Aux!$H$40)
Name Lista_Estilos11: _xlfn.ANCHORARRAY(Aux!$H$44)
Name Lista_Estilos12: _xlfn.ANCHORARRAY(Aux!$H$48)
Name Lista_Estilos13: _xlfn.ANCHORARRAY(Aux!$H$52)
Name Lista_Estilos14: _xlfn.ANCHORARRAY(Aux!$H$56)
Name Lista_Estilos15: _xlfn.ANCHORARRAY(Aux!$H$60)
Name Lista_Estilos16: _xlfn.ANCHORARRAY(Aux!$H$64)
Name Lista_Estilos17: _xlfn.ANCHORARRAY(Aux!$H$68)
Name Lista_Estilos18: _xlfn.ANCHORARRAY(Aux!$H$72)
Name Lista_Estilos19: _xlfn.ANCHORARRAY(Aux!$H$76)
Name Lista_Estilos2: _xlfn.ANCHORARRAY(Aux!$H$8)
Name Lista_Estilos20: _xlfn.ANCHORARRAY(Aux!$H$80)
Name Lista_Estilos3: _xlfn.ANCHORARRAY(Aux!$H$12)
Name Lista_Estilos4: _xlfn.ANCHORARRAY(Aux!$H$16)
Name Lista_Estilos5: _xlfn.ANCHORARRAY(Aux!$H$20)
Name Lista_Estilos6: _xlfn.ANCHORARRAY(Aux!$H$24)
Name Lista_Estilos7: _xlfn.ANCHORARRAY(Aux!$H$28)
Name Lista_Estilos8: _xlfn.ANCHORARRAY(Aux!$H$32)
Name Lista_Estilos9: _xlfn.ANCHORARRAY(Aux!$H$36)
Name Lista_Marca1: _xlfn.ANCHORARRAY(Aux!$F$4)
Name Lista_Marca10: _xlfn.ANCHORARRAY(Aux!$F$31)
Name Lista_Marca11: _xlfn.ANCHORARRAY(Aux!$F$34)
Name Lista_Marca12: _xlfn.ANCHORARRAY(Aux!$F$37)
Name Lista_Marca13: _xlfn.ANCHORARRAY(Aux!$F$40)
Name Lista_Marca14: _xlfn.ANCHORARRAY(Aux!$F$43)
Name Lista_Marca15: _xlfn.ANCHORARRAY(Aux!$F$46)
Name Lista_Marca16: _xlfn.ANCHORARRAY(Aux!$F$49)
Name Lista_Marca17: _xlfn.ANCHORARRAY(Aux!$F$52)
Name Lista_Marca18: _xlfn.ANCHORARRAY(Aux!$F$55)
Name Lista_Marca19: _xlfn.ANCHORARRAY(Aux!$F$58)
Name Lista_Marca2: _xlfn.ANCHORARRAY(Aux!$F$7)
Name Lista_Marca20: _xlfn.ANCHORARRAY(Aux!$F$61)
Name Lista_Marca3: _xlfn.ANCHORARRAY(Aux!$F$10)
Name Lista_Marca4: _xlfn.ANCHORARRAY(Aux!$F$13)
Name Lista_Marca5: _xlfn.ANCHORARRAY(Aux!$F$16)
Name Lista_Marca6: _xlfn.ANCHORARRAY(Aux!$F$19)
Name Lista_Marca7: _xlfn.ANCHORARRAY(Aux!$F$22)
Name Lista_Marca8: _xlfn.ANCHORARRAY(Aux!$F$25)
Name Lista_Marca9: _xlfn.ANCHORARRAY(Aux!$F$28)

Sheet Rango
A1: id_rango | B1: descripcion | C1: min | D1: max
A2: 1 | B2: Unidad | C2: 1 | D2: 5
A3: 2 | B3: Media docena | C3: 6 | D3: 11
A4: 3 | B4: Docena o más | C4: 12 | D4: 999

Sheet Talla-Prenda
A1: id_talla_prenda | B1: id_talla | C1: id_prenda
A2: 1 | B2: 1 | C2: 1
A3: 2 | B3: 2 | C3: 1
A4: 3 | B4: 3 | C4: 1
A5: 4 | B5: 4 | C5: 1
A6: 5 | B6: 5 | C6: 1
A7: 6 | B7: 6 | C7: 1
A8: 7 | B8: 7 | C8: 1
A9: 8 | B9: 8 | C9: 1
A10: 9 | B10: 9 | C10: 1
A11: 10 | B11: 10 | C11: 1
A12: 11 | B12: 11 | C12: 1
A13: 12 | B13: 12 | C13: 1
... A32: 31 | B32: 11 | C32: 4

Sheet Tela-Color
A1: id_tela_color | B1: id_tela | C1: id_color
A2: 1 | B2: 1 | C2: 1
A3: 2 | B3: 1 | C3: 2
A4: 3 | B4: 1 | C4: 3
A5: 4 | B5: 1 | C5: 4
A6: 5 | B6: 1 | C6: 5
A7: 6 | B7: 1 | C7: 6
A8: 7 | B8: 1 | C8: 7
A9: 8 | B9: 1 | C9: 8
A10: 9 | B10: 1 | C10: 9
A11: 10 | B11: 1 | C11: 10
A12: 11 | B12: 1 | C12: 11
A13: 12 | B13: 1 | C13: 12
... A25: 24 | B25: 4 | C25: 13

Sheet Estilo-Talla
A1: id_estilo_talla | B1: id_estilo | C1: id_talla | D1: id_prenda
A2: 1 | B2: 1 | C2: 1 | D2: 1
A3: 2 | B3: 1 | C3: 2 | D3: 1
A4: 3 | B4: 1 | C4: 3 | D4: 1
A5: 4 | B5: 1 | C5: 4 | D5: 1
A6: 5 | B6: 1 | C6: 5 | D6: 1
A7: 6 | B7: 1 | C7: 6 | D7: 1
A8: 7 | B8: 2 | C8: 7 | D8: 1
A9: 8 | B9: 2 | C9: 8 | D9: 1
A10: 9 | B10: 2 | C10: 9 | D10: 1
A11: 10 | B11: 2 | C11: 10 | D11: 1
A12: 11 | B12: 2 | C12: 11 | D12: 1
A13: 12 | B13: 2 | C13: 12 | D13: 1
... A41: 40 | B41: 5 | C41: 12 | D41: 2

Sheet Tela-Prenda
A1: id_tela_prenda | B1: id_tela | C1: id_prenda
A2: 1 | B2: 1 | C2: 1
A3: 2 | B3: 2 | C3: 1
A4: 3 | B4: 3 | C4: 2
A5: 4 | B5: 4 | C5: 2
A6: 5 | B6: 1 | C6: 3

Sheet Precios-Polos
A1: id_precio_polo | B1: id_contexto_precio | C1: id_tela | D1: id_talla | E1: id_rango | F1: precio
A2: 1 | B2: 1 | C2: 1 | D2: 1 | E2: 1 | F2: 33
A3: 2 | B3: 1 | C3: 1 | D3: 1 | E3: 2 | F3: 28
A4: 3 | B4: 1 | C4: 1 | D4: 1 | E4: 3 | F4: 23
A5: 4 | B5: 1 | C5: 1 | D5: 2 | E5: 1 | F5: 33
A6: 5 | B6: 1 | C6: 1 | D6: 2 | E6: 2 | F6: 28
A7: 6 | B7: 1 | C7: 1 | D7: 2 | E7: 3 | F7: 23
A8: 7 | B8: 1 | C8: 1 | D8: 3 | E8: 1 | F8: 33
A9: 8 | B9: 1 | C9: 1 | D9: 3 | E9: 2 | F9: 28
A10: 9 | B10: 1 | C10: 1 | D10: 3 | E10: 3 | F10: 23
A11: 10 | B11: 1 | C11: 1 | D11: 4 | E11: 1 | F11: 33
A12: 11 | B12: 1 | C12: 1 | D12: 4 | E12: 2 | F12: 28
A13: 12 | B13: 1 | C13: 1 | D13: 4 | E13: 3 | F13: 23
... A217: 216 | B217: 3 | C217: 2 | D217: 12 | E217: 3 | F217: 26

Sheet Precio-Poleras
A1: id_precio_polera | B1: id_contexto_precio | C1: id_tela | D1: id_estilo | E1: id_talla | F1: id_rango | G1: precio
A2: 1 | B2: 1 | C2: 3 | D2: 4 | E2: 1 | F2: 1 | G2: 50
A3: 2 | B3: 1 | C3: 3 | D3: 4 | E3: 1 | F3: 2 | G3: 45
A4: 3 | B4: 1 | C4: 3 | D4: 4 | E4: 1 | F4: 3 | G4: 40
A5: 4 | B5: 1 | C5: 3 | D5: 4 | E5: 2 | F5: 1 | G5: 50
A6: 5 | B6: 1 | C6: 3 | D6: 4 | E6: 2 | F6: 2 | G6: 45
A7: 6 | B7: 1 | C7: 3 | D7: 4 | E7: 2 | F7: 3 | G7: 40
A8: 7 | B8: 1 | C8: 3 | D8: 4 | E8: 3 | F8: 1 | G8: 50
A9: 8 | B9: 1 | C9: 3 | D9: 4 | E9: 3 | F9: 2 | G9: 45
A10: 9 | B10: 1 | C10: 3 | D10: 4 | E10: 3 | F10: 3 | G10: 40
A11: 10 | B11: 1 | C11: 3 | D11: 4 | E11: 4 | F11: 1 | G11: 50
A12: 11 | B12: 1 | C12: 3 | D12: 4 | E12: 4 | F12: 2 | G12: 45
A13: 12 | B13: 1 | C13: 3 | D13: 4 | E13: 4 | F13: 3 | G13: 40
... A289: 288 | B289: 2 | C289: 4 | D289: 5 | E289: 12 | F289: 3 | G289: 40

Sheet Precio-Boxers
A1: id_precio_boxer | B1: id_contexto_precio | C1: id_marca | D1: id_talla | E1: precio
A2: 1 | B2: 1 | C2: 1 | D2: 8 | E2: 35
A3: 2 | B3: 1 | C3: 1 | D3: 9 | E3: 35
A4: 3 | B4: 1 | C4: 1 | D4: 10 | E4: 35
A5: 4 | B5: 1 | C5: 1 | D5: 11 | E5: 38
A6: 5 | B6: 1 | C6: 2 | D6: 8 | E6: 25
A7: 6 | B7: 1 | C7: 2 | D7: 9 | E7: 25
A8: 7 | B8: 1 | C8: 2 | D8: 10 | E8: 25
A9: 8 | B9: 1 | C9: 2 | D9: 11 | E9: 28
A10: 9 | B10: 2 | C10: 1 | D10: 8 | E10: 30
A11: 10 | B11: 2 | C11: 1 | D11: 9 | E11: 30
A12: 11 | B12: 2 | C12: 1 | D12: 10 | E12: 30
A13: 12 | B13: 2 | C13: 1 | D13: 11 | E13: 33
... A17: 16 | B17: 2 | C17: 2 | D17: 11 | E17: 23

Sheet Precio-Bodys
A1: id_precio_body | B1: id_contexto_precio | C1: id_talla | D1: id_rango | E1: precio
A2: 1 | B2: 1 | C2: 13 | D2: 1 | E2: 30
A3: 2 | B3: 1 | C3: 13 | D3: 2 | E3: 25
A4: 3 | B4: 1 | C4: 13 | D4: 3 | E4: 23
A5: 4 | B5: 1 | C5: 14 | D5: 1 | E5: 30
A6: 5 | B6: 1 | C6: 14 | D6: 2 | E6: 25
A7: 6 | B7: 1 | C7: 14 | D7: 3 | E7: 23
A8: 7 | B8: 1 | C8: 15 | D8: 1 | E8: 30
A9: 8 | B9: 1 | C9: 15 | D9: 2 | E9: 25
A10: 9 | B10: 1 | C10: 15 | D10: 3 | E10: 23
A11: 10 | B11: 2 | C11: 13 | D11: 1 | E11: 23
A12: 11 | B12: 2 | C12: 13 | D12: 2 | E12: 20
A13: 12 | B13: 2 | C13: 13 | D13: 3 | E13: 18
... A19: 18 | B19: 2 | C19: 15 | D19: 3 | E19: 18

Sheet Prenda
A1: id_prenda | B1: prenda
A2: 1 | B2: Polo
A3: 2 | B3: Polera
A4: 3 | B4: Body
A5: 4 | B5: Boxer

Sheet Contexto
A1: id_contexto_precio | B1: nombre_contexto | C1: tipo_contexto | D1: estado
A2: 1 | B2: Precio General | C2: Base | D2: Activo
A3: 2 | B3: Navidad y Año Nuevo | C3: Campaña | D3: Activo
A4: 3 | B4: Graduación | C4: Campaña | D4: Activo
A5: 4 | B5: Verano | C5: Campaña | D5: Planificado
A6: 5 | B6: San Valentín | C6: Campaña | D6: Planificado
A7: 6 | B7: Día de la Madre | C7: Campaña | D7: Histórico
A8: 7 | B8: Día de la Educación Inicial | C8: Campaña | D8: Histórico
A9: 8 | B9: Día del Padre | C9: Campaña | D9: Histórico

Sheet Color
A1: id_color | B1: color
A2: 1 | B2: Amarillo
A3: 2 | B3: Anaranjado
A4: 3 | B4: Azul
A5: 4 | B5: Blanco
A6: 5 | B6: Celeste Bebé
A7: 6 | B7: Fucsia
A8: 7 | B8: Lila
A9: 8 | B9: Negro
A10: 9 | B10: Rojo
A11: 10 | B11: Rosado
A12: 11 | B12: Turqueza
A13: 12 | B13: Verde
A14: 13 | B14: Melange

Sheet Talla
A1: id_talla | B1: talla | C1: tipo
A2: 1 | B2: T2 | C2: Niño
A3: 2 | B3: T4 | C3: Niño
A4: 3 | B4: T6 | C4: Niño
A5: 4 | B5: T8 | C5: Niño
A6: 5 | B6: T10 | C6: Niño
A7: 6 | B7: T12 | C7: Niño
A8: 7 | B8: T14 | C8: Adulto
A9: 8 | B9: S | C9: Adulto
A10: 9 | B10: M | C10: Adulto
A11: 10 | B11: L | C11: Adulto
A12: 11 | B12: XL | C12: Adulto
A13: 12 | B13: XXL | C13: Adulto
... A16: 15 | B16: 8 - 11 m | C16: Bebé

Sheet Tela
A1: id_tela | B1: nombre_tela
A2: 1 | B2: Alta calidad
A3: 2 | B3: Calidad intermedia
A4: 3 | B4: Franela
A5: 4 | B5: Policoton

Sheet Estilo
A1: id_estilo | B1: nombre_estilo | C1: id_prenda
A2: 1 | B2: Niño | C2: 1
A3: 2 | B3: Recto | C3: 1
A4: 3 | B4: Princesa | C4: 1
A5: 4 | B5: Capucha + bolsillo | C5: 2
A6: 5 | B6: Cuello redondo | C6: 2

Sheet Marca
A1: id_marca | B1: nombre_marca | C1: id_prenda
A2: 1 | B2: Boston | C2: 4
A3: 2 | B3: Calvin Klein | C3: 4

Sheet Aux
B2: Lista_Telas# | D2: Lista_Colores# | F2: Lista_Marca# | H2: Lista_Estilos# | J2: Lista_Tallas#
B4: {=_xlfn._xlws.FILTER( tb_tela[nombre_tela], ISNUMBER( MATCH( tb_tela[id_tela], _xlfn._xlws.FILTER( tb_tela_prenda[id_tela], tb_tela_prenda[id_prenda]=Cotizador!L7 ), 0 ) ), "No necesario" )} -> Alta calidad | D4: {=_xlfn._xlws.FILTER( tb_color[color], ISNUMBER( MATCH( tb_color[id_color], _xlfn._xlws.FILTER( tb_tela_color[id_color], tb_tela_color[id_tela]=Cotizador!N7 ), 0 ) ),"No necesario" )} -> Amarillo | F4: {=_xlfn._xlws.FILTER( tb_marca[nombre_marca], tb_marca[id_prenda]=Cotizador!L7, "No necesario" )} -> No necesario | H4: {=_xlfn._xlws.FILTER(tb_estilo[nombre_estilo], tb_estilo[id_prenda]=Cotizador!L7, "No necesario")} -> Niño | J4: {=IF( OR(Cotizador!L7=3,Cotizador!L7=4), _xlfn._xlws.FILTER( tb_talla[talla], ISNUMBER( MATCH( tb_talla[id_talla], _xlfn._xlws.FILTER( tb_talla_prenda[id_talla], tb_talla_prenda[id_prenda]=Cotizador!L7 ), 0 ) ), "No hay tallas" ), _xlfn._xlws.FILTER( tb_talla[talla], ISNUMBER( MATCH( tb_talla[id_talla], _xlfn._xlws.FILTER( tb_estilo_talla[id_talla], (tb_estilo_talla[id_prenda]=Cotizador!L7)* (tb_estilo_talla[id_estilo]=Cotizador!O7) ), 0 ) ), "No hay tallas" ) )} -> T14
B5: Calidad intermedia | D5: Blanco | H5: Recto | J5: S
D6: Negro | H6: Princesa | J6: M
B7: {=_xlfn._xlws.FILTER( tb_tela[nombre_tela], ISNUMBER( MATCH( tb_tela[id_tela], _xlfn._xlws.FILTER( tb_tela_prenda[id_tela], tb_tela_prenda[id_prenda]=Cotizador!L8 ), 0 ) ), "No necesario" )} -> Alta calidad | D7: Rojo | F7: {=_xlfn._xlws.FILTER( tb_marca[nombre_marca], tb_marca[id_prenda]=Cotizador!L8, "No necesario" )} -> No necesario | J7: L
B8: Calidad intermedia | D8: Rosado | H8: {=_xlfn._xlws.FILTER(tb_estilo[nombre_estilo], tb_estilo[id_prenda]=Cotizador!L8, "No necesario")} -> Niño | J8: XL
D9: Verde | H9: Recto | J9: XXL
B10: {=_xlfn._xlws.FILTER( tb_tela[nombre_tela], ISNUMBER( MATCH( tb_tela[id_tela], _xlfn._xlws.FILTER( tb_tela_prenda[id_tela], tb_tela_prenda[id_prenda]=Cotizador!L9 ), 0 ) ), "No necesario" )} -> Alta calidad | F10: {=_xlfn._xlws.FILTER( tb_marca[nombre_marca], tb_marca[id_prenda]=Cotizador!L9, "No necesario" )} -> No necesario | H10: Princesa
B11: Calidad intermedia
H12: {=_xlfn._xlws.FILTER(tb_estilo[nombre_estilo], tb_estilo[id_prenda]=Cotizador!L9, "No necesario")} -> Niño
B13: {=_xlfn._xlws.FILTER( tb_tela[nombre_tela], ISNUMBER( MATCH( tb_tela[id_tela], _xlfn._xlws.FILTER( tb_tela_prenda[id_tela], tb_tela_prenda[id_prenda]=Cotizador!L10 ), 0 ) ), "No necesario" )} -> No necesario | F13: {=_xlfn._xlws.FILTER( tb_marca[nombre_marca], tb_marca[id_prenda]=Cotizador!L10, "No necesario" )} -> No necesario | H13: Recto
H14: Princesa
B16: {=_xlfn._xlws.FILTER( tb_tela[nombre_tela], ISNUMBER( MATCH( tb_tela[id_tela], _xlfn._xlws.FILTER( tb_tela_prenda[id_tela], tb_tela_prenda[id_prenda]=Cotizador!L11 ), 0 ) ), "No necesario" )} -> No necesario | F16: {=_xlfn._xlws.FILTER( tb_marca[nombre_marca], tb_marca[id_prenda]=Cotizador!L11, "No necesario" )} -> No necesario | H16: {=_xlfn._xlws.FILTER(tb_estilo[nombre_estilo], tb_estilo[id_prenda]=Cotizador!L10, "No necesario")} -> No necesario
D17: {=_xlfn._xlws.FILTER( tb_color[color], ISNUMBER( MATCH( tb_color[id_color], _xlfn._xlws.FILTER( tb_tela_color[id_color], tb_tela_color[id_tela]=Cotizador!N8 ), 0 ) ),"No necesario" )} -> Amarillo | J17: {=IF( OR(Cotizador!L8=3,Cotizador!L8=4), _xlfn._xlws.FILTER( tb_talla[talla], ISNUMBER( MATCH( tb_talla[id_talla], _xlfn._xlws.FILTER( tb_talla_prenda[id_talla], tb_talla_prenda[id_prenda]=Cotizador!L8 ), 0 ) ), "No hay tallas" ), _xlfn._xlws.FILTER( tb_talla[talla], ISNUMBER( MATCH( tb_talla[id_talla], _xlfn._xlws.FILTER( tb_estilo_talla[id_talla], (tb_estilo_talla[id_prenda]=Cotizador!L8)* (tb_estilo_talla[id_estilo]=Cotizador!O8) ), 0 ) ), "No hay tallas" ) )} -> T14
D18: Anaranjado | J18: S
B19: {=_xlfn._xlws.FILTER( tb_tela[nombre_tela], ISNUMBER( MATCH( tb_tela[id_tela], _xlfn._xlws.FILTER( tb_tela_prenda[id_tela], tb_tela_prenda[id_prenda]=Cotizador!L12 ), 0 ) ), "No necesario" )} -> No necesario | D19: Azul | F19: {=_xlfn._xlws.FILTER( tb_marca[nombre_marca], tb_marca[id_prenda]=Cotizador!L12, "No necesario" )} -> No necesario | J19: M
D20: Blanco | H20: {=_xlfn._xlws.FILTER(tb_estilo[nombre_estilo], tb_estilo[id_prenda]=Cotizador!L11, "No necesario")} -> No necesario | J20: L
D21: Celeste Bebé | J21: XL
B22: {=_xlfn._xlws.FILTER( tb_tela[nombre_tela], ISNUMBER( MATCH( tb_tela[id_tela], _xlfn._xlws.FILTER( tb_tela_prenda[id_tela], tb_tela_prenda[id_prenda]=Cotizador!L13 ), 0 ) ), "No necesario" )} -> No necesario | D22: Fucsia | F22: {=_xlfn._xlws.FILTER( tb_marca[nombre_marca], tb_marca[id_prenda]=Cotizador!L13, "No necesario" )} -> No necesario | J22: XXL
D23: Lila
D24: Negro | H24: {=_xlfn._xlws.FILTER(tb_estilo[nombre_estilo], tb_estilo[id_prenda]=Cotizador!L12, "No necesario")} -> No necesario
B25: {=_xlfn._xlws.FILTER( tb_tela[nombre_tela], ISNUMBER( MATCH( tb_tela[id_tela], _xlfn._xlws.FILTER( tb_tela_prenda[id_tela], tb_tela_prenda[id_prenda]=Cotizador!L14 ), 0 ) ), "No necesario" )} -> No necesario | D25: Rojo | F25: {=_xlfn._xlws.FILTER( tb_marca[nombre_marca], tb_marca[id_prenda]=Cotizador!L14, "No necesario" )} -> No necesario
D26: Rosado
D27: Turqueza
B28: {=_xlfn._xlws.FILTER( tb_tela[nombre_tela], ISNUMBER( MATCH( tb_tela[id_tela], _xlfn._xlws.FILTER( tb_tela_prenda[id_tela], tb_tela_prenda[id_prenda]=Cotizador!L15 ), 0 ) ), "No necesario" )} -> No necesario | D28: Verde | F28: {=_xlfn._xlws.FILTER( tb_marca[nombre_marca], tb_marca[id_prenda]=Cotizador!L15, "No necesario" )} -> No necesario | H28: {=_xlfn._xlws.FILTER(tb_estilo[nombre_estilo], tb_estilo[id_prenda]=Cotizador!L13, "No necesario")} -> No necesario
J30: {=IF( OR(Cotizador!L9=3,Cotizador!L9=4), _xlfn._xlws.FILTER( tb_talla[talla], ISNUMBER( MATCH( tb_talla[id_talla], _xlfn._xlws.FILTER( tb_talla_prenda[id_talla], tb_talla_prenda[id_prenda]=Cotizador!L9 ), 0 ) ), "No hay tallas" ), _xlfn._xlws.FILTER( tb_talla[talla], ISNUMBER( MATCH( tb_talla[id_talla], _xlfn._xlws.FILTER( tb_estilo_talla[id_talla], (tb_estilo_talla[id_prenda]=Cotizador!L9)* (tb_estilo_talla[id_estilo]=Cotizador!O9) ), 0 ) ), "No hay tallas" ) )} -> T14
B31: {=_xlfn._xlws.FILTER( tb_tela[nombre_tela], ISNUMBER( MATCH( tb_tela[id_tela], _xlfn._xlws.FILTER( tb_tela_prenda[id_tela], tb_tela_prenda[id_prenda]=Cotizador!L16 ), 0 ) ), "No necesario" )} -> No necesario | D31: {=_xlfn._xlws.FILTER( tb_color[color], ISNUMBER( MATCH( tb_color[id_color], _xlfn._xlws.FILTER( tb_tela_color[id_color], tb_tela_color[id_tela]=Cotizador!N9 ), 0 ) ),"No necesario" )} -> Amarillo | F31: {=_xlfn._xlws.FILTER( tb_marca[nombre_marca], tb_marca[id_prenda]=Cotizador!L16, "No necesario" )} -> No necesario | J31: S
D32: Anaranjado | H32: {=_xlfn._xlws.FILTER(tb_estilo[nombre_estilo], tb_estilo[id_prenda]=Cotizador!L14, "No necesario")} -> No necesario | J32: M
D33: Azul | J33: L
B34: {=_xlfn._xlws.FILTER( tb_tela[nombre_tela], ISNUMBER( MATCH( tb_tela[id_tela], _xlfn._xlws.FILTER( tb_tela_prenda[id_tela], tb_tela_prenda[id_prenda]=Cotizador!L17 ), 0 ) ), "No necesario" )} -> No necesario | D34: Blanco | F34: {=_xlfn._xlws.FILTER( tb_marca[nombre_marca], tb_marca[id_prenda]=Cotizador!L17, "No necesario" )} -> No necesario | J34: XL
D35: Celeste Bebé | J35: XXL
D36: Fucsia | H36: {=_xlfn._xlws.FILTER(tb_estilo[nombre_estilo], tb_estilo[id_prenda]=Cotizador!L15, "No necesario")} -> No necesario
B37: {=_xlfn._xlws.FILTER( tb_tela[nombre_tela], ISNUMBER( MATCH( tb_tela[id_tela], _xlfn._xlws.FILTER( tb_tela_prenda[id_tela], tb_tela_prenda[id_prenda]=Cotizador!L18 ), 0 ) ), "No necesario" )} -> No necesario | D37: Lila | F37: {=_xlfn._xlws.FILTER( tb_marca[nombre_marca], tb_marca[id_prenda]=Cotizador!L18, "No necesario" )} -> No necesario
D38: Negro
D39: Rojo
B40: {=_xlfn._xlws.FILTER( tb_tela[nombre_tela], ISNUMBER( MATCH( tb_tela[id_tela], _xlfn._xlws.FILTER( tb_tela_prenda[id_tela], tb_tela_prenda[id_prenda]=Cotizador!L19 ), 0 ) ), "No necesario" )} -> No necesario | D40: Rosado | F40: {=_xlfn._xlws.FILTER( tb_marca[nombre_marca], tb_marca[id_prenda]=Cotizador!L19, "No necesario" )} -> No necesario | H40: {=_xlfn._xlws.FILTER(tb_estilo[nombre_estilo], tb_estilo[id_prenda]=Cotizador!L16, "No necesario")} -> No necesario
D41: Turqueza
D42: Verde
B43: {=_xlfn._xlws.FILTER( tb_tela[nombre_tela], ISNUMBER( MATCH( tb_tela[id_tela], _xlfn._xlws.FILTER( tb_tela_prenda[id_tela], tb_tela_prenda[id_prenda]=Cotizador!L20 ), 0 ) ), "No necesario" )} -> No necesario | F43: {=_xlfn._xlws.FILTER( tb_marca[nombre_marca], tb_marca[id_prenda]=Cotizador!L20, "No necesario" )} -> No necesario | J43: {=IF( OR(Cotizador!L10=3,Cotizador!L10=4), _xlfn._xlws.FILTER( tb_talla[talla], ISNUMBER( MATCH( tb_talla[id_talla], _xlfn._xlws.FILTER( tb_talla_prenda[id_talla], tb_talla_prenda[id_prenda]=Cotizador!L10 ), 0 ) ), "No hay tallas" ), _xlfn._xlws.FILTER( tb_talla[talla], ISNUMBER( MATCH( tb_talla[id_talla], _xlfn._xlws.FILTER( tb_estilo_talla[id_talla], (tb_estilo_talla[id_prenda]=Cotizador!L10)* (tb_estilo_talla[id_estilo]=Cotizador!O10) ), 0 ) ), "No hay tallas" ) )} -> No hay tallas
H44: {=_xlfn._xlws.FILTER(tb_estilo[nombre_estilo], tb_estilo[id_prenda]=Cotizador!L17, "No necesario")} -> No necesario
...

Sheet Cotizador
U4: COTIZACIÓN
C6: Prenda | D6: Contexto | E6: Tela | F6: Color | G6: Estilo | H6: Talla | I6: Marca | J6: Cantidad | L6: Id_Prenda | M6: Id_Ctxto | N6: Id_Tela | O6: Id_Estilo | P6: Id_Talla | Q6: Id_Marca | R6: T x Prendas | S6: Id_Rango | V6: Descripción de producto | W6: Precio Unitario | X6: ADC. / DSCT. | Y6: Cantidad | Z6: Importe
C7: Polo | D7: Precio General | E7: Calidad intermedia | F7: Negro | G7: Recto | H7: L | I7: No necesario | J7: 2 | L7: =_xlfn.XLOOKUP(C7,tb_prenda[prenda],tb_prenda[id_prenda],"No encontrado") -> 1 | M7: =_xlfn.XLOOKUP(D7,tb_contexto_precio[nombre_contexto],tb_contexto_precio[id_contexto_precio],"No encontrado") -> 1 | N7: =_xlfn.XLOOKUP(E7,tb_tela[nombre_tela],tb_tela[id_tela],"No encontrado") -> 2 | O7: =_xlfn.XLOOKUP(G7,tb_estilo[nombre_estilo],tb_estilo[id_estilo],"No encontrado") -> 2 | P7: =_xlfn.XLOOKUP(H7,tb_talla[talla],tb_talla[id_talla],"No encontrado") -> 10 | Q7: =_xlfn.XLOOKUP(I7,tb_marca[nombre_marca],tb_marca[id_marca],"No encontrado") -> No encontrado | R7: =SUMIF($C$7:$C$11,C7,$J$7:$J$11) -> 5 | S7: =_xlfn.XLOOKUP(R7,tb_rango_cantidad[min],tb_rango_cantidad[id_rango],,-1) -> 1 | V7: =UPPER(IF(L7=1,C7&" de "&E7&" "&F7&" "&G7&" "&H7,IF(L7=2,C7&" de "&E7&" "&F7&" "&G7&" "&H7,IF(L7=3,C7&" "&F7&" TALLA "&H7,C7&" "&I7&" TALLA "&H7)))) -> POLO DE CALIDAD INTERMEDIA NEGRO RECTO L | W7: {=IF(L7=1, _xlfn.XLOOKUP(1, (tb_precio_polos[id_contexto_precio]=M7)* (tb_precio_polos[id_tela]=N7)* (tb_precio_polos[id_talla]=P7)* (tb_precio_polos[id_rango]=S7), tb_precio_polos[precio] ), IF(L7=2, _xlfn.XLOOKUP(1, (tb_precio_poleras[id_contexto_precio]=M7)* (tb_precio_poleras[id_tela]=N7)* (tb_precio_poleras[id_estilo]=O7)* (tb_precio_poleras[id_talla]=P7)* (tb_precio_poleras[id_rango]=S7), tb_precio_poleras[precio] ), IF(L7=3, _xlfn.XLOOKUP(1, (tb_precio_body[id_contexto_precio]=M7)* (tb_precio_body[id_talla]=P7)* (tb_precio_body[id_rango]=S7), tb_precio_body[precio] ), IF(L7=4, _xlfn.XLOOKUP(1, (tb_precio_boxer[id_contexto_precio]=M7)* (tb_precio_boxer[id_marca]=Q7)* (tb_precio_boxer[id_talla]=P7), tb_precio_boxer[precio] ), "" ))))} -> 28 | Y7: =J7 -> 2 | Z7: =(W7+X7)*Y7 -> 56
C8: Polo | D8: Precio General | E8: Alta calidad | F8: Blanco | G8: Recto | H8: M | I8: No necesario | J8: 2 | L8: =_xlfn.XLOOKUP(C8,tb_prenda[prenda],tb_prenda[id_prenda],"No encontrado") -> 1 | M8: =_xlfn.XLOOKUP(D8,tb_contexto_precio[nombre_contexto],tb_contexto_precio[id_contexto_precio],"No encontrado") -> 1 | N8: =_xlfn.XLOOKUP(E8,tb_tela[nombre_tela],tb_tela[id_tela],"No encontrado") -> 1 | O8: =_xlfn.XLOOKUP(G8,tb_estilo[nombre_estilo],tb_estilo[id_estilo],"No encontrado") -> 2 | P8: =_xlfn.XLOOKUP(H8,tb_talla[talla],tb_talla[id_talla],"No encontrado") -> 9 | Q8: =_xlfn.XLOOKUP(I8,tb_marca[nombre_marca],tb_marca[id_marca],"No encontrado") -> No encontrado | R8: =SUMIF($C$7:$C$11,C8,$J$7:$J$11) -> 5 | S8: =_xlfn.XLOOKUP(R8,tb_rango_cantidad[min],tb_rango_cantidad[id_rango],,-1) -> 1 | V8: =UPPER(IF(L8=1,C8&" de "&E8&" "&F8&" "&G8&" "&H8,IF(L8=2,C8&" de "&E8&" "&F8&" "&G8&" "&H8,IF(L8=3,C8&" "&F8&" TALLA "&H8,C8&" "&I8&" TALLA "&H8)))) -> POLO DE ALTA CALIDAD BLANCO RECTO M | W8: {=IF(L8=1, _xlfn.XLOOKUP(1, (tb_precio_polos[id_contexto_precio]=M8)* (tb_precio_polos[id_tela]=N8)* (tb_precio_polos[id_talla]=P8)* (tb_precio_polos[id_rango]=S8), tb_precio_polos[precio] ), IF(L8=2, _xlfn.XLOOKUP(1, (tb_precio_poleras[id_contexto_precio]=M8)* (tb_precio_poleras[id_tela]=N8)* (tb_precio_poleras[id_estilo]=O8)* (tb_precio_poleras[id_talla]=P8)* (tb_precio_poleras[id_rango]=S8), tb_precio_poleras[precio] ), IF(L8=3, _xlfn.XLOOKUP(1, (tb_precio_body[id_contexto_precio]=M8)* (tb_precio_body[id_talla]=P8)* (tb_precio_body[id_rango]=S8), tb_precio_body[precio] ), IF(L8=4, _xlfn.XLOOKUP(1, (tb_precio_boxer[id_contexto_precio]=M8)* (tb_precio_boxer[id_marca]=Q8)* (tb_precio_boxer[id_talla]=P8), tb_precio_boxer[precio] ), "" ))))} -> 35 | Y8: =J8 -> 2 | Z8: =(W8+X8)*Y8 -> 70
C9: Polo | D9: Precio General | E9: Alta calidad | F9: Azul | G9: Recto | H9: S | I9: No necesario | J9: 1 | L9: =_xlfn.XLOOKUP(C9,tb_prenda[prenda],tb_prenda[id_prenda],"No encontrado") -> 1 | M9: =_xlfn.XLOOKUP(D9,tb_contexto_precio[nombre_contexto],tb_contexto_precio[id_contexto_precio],"No encontrado") -> 1 | N9: =_xlfn.XLOOKUP(E9,tb_tela[nombre_tela],tb_tela[id_tela],"No encontrado") -> 1 | O9: =_xlfn.XLOOKUP(G9,tb_estilo[nombre_estilo],tb_estilo[id_estilo],"No encontrado") -> 2 | P9: =_xlfn.XLOOKUP(H9,tb_talla[talla],tb_talla[id_talla],"No encontrado") -> 8 | Q9: =_xlfn.XLOOKUP(I9,tb_marca[nombre_marca],tb_marca[id_marca],"No encontrado") -> No encontrado | R9: =SUMIF($C$7:$C$11,C9,$J$7:$J$11) -> 5 | S9: =_xlfn.XLOOKUP(R9,tb_rango_cantidad[min],tb_rango_cantidad[id_rango],,-1) -> 1 | V9: =UPPER(IF(L9=1,C9&" de "&E9&" "&F9&" "&G9&" "&H9,IF(L9=2,C9&" de "&E9&" "&F9&" "&G9&" "&H9,IF(L9=3,C9&" "&F9&" TALLA "&H9,C9&" "&I9&" TALLA "&H9)))) -> POLO DE ALTA CALIDAD AZUL RECTO S | W9: {=IF(L9=1, _xlfn.XLOOKUP(1, (tb_precio_polos[id_contexto_precio]=M9)* (tb_precio_polos[id_tela]=N9)* (tb_precio_polos[id_talla]=P9)* (tb_precio_polos[id_rango]=S9), tb_precio_polos[precio] ), IF(L9=2, _xlfn.XLOOKUP(1, (tb_precio_poleras[id_contexto_precio]=M9)* (tb_precio_poleras[id_tela]=N9)* (tb_precio_poleras[id_estilo]=O9)* (tb_precio_poleras[id_talla]=P9)* (tb_precio_poleras[id_rango]=S9), tb_precio_poleras[precio] ), IF(L9=3, _xlfn.XLOOKUP(1, (tb_precio_body[id_contexto_precio]=M9)* (tb_precio_body[id_talla]=P9)* (tb_precio_body[id_rango]=S9), tb_precio_body[precio] ), IF(L9=4, _xlfn.XLOOKUP(1, (tb_precio_boxer[id_contexto_precio]=M9)* (tb_precio_boxer[id_marca]=Q9)* (tb_precio_boxer[id_talla]=P9), tb_precio_boxer[precio] ), "" ))))} -> 35 | Y9: =J9 -> 1 | Z9: =(W9+X9)*Y9 -> 35
L10: =_xlfn.XLOOKUP(C10,tb_prenda[prenda],tb_prenda[id_prenda],"No encontrado") -> No encontrado | M10: =_xlfn.XLOOKUP(D10,tb_contexto_precio[nombre_contexto],tb_contexto_precio[id_contexto_precio],"No encontrado") -> No encontrado | N10: =_xlfn.XLOOKUP(E10,tb_tela[nombre_tela],tb_tela[id_tela],"No encontrado") -> No encontrado | O10: =_xlfn.XLOOKUP(G10,tb_estilo[nombre_estilo],tb_estilo[id_estilo],"No encontrado") -> No encontrado | P10: =_xlfn.XLOOKUP(H10,tb_talla[talla],tb_talla[id_talla],"No encontrado") -> No encontrado | Q10: =_xlfn.XLOOKUP(I10,tb_marca[nombre_marca],tb_marca[id_marca],"No encontrado") -> No encontrado | R10: =SUMIF($C$7:$C$11,C10,$J$7:$J$11) -> 0 | S10: =_xlfn.XLOOKUP(R10,tb_rango_cantidad[min],tb_rango_cantidad[id_rango],,-1) -> #N/A
L11: =_xlfn.XLOOKUP(C11,tb_prenda[prenda],tb_prenda[id_prenda],"No encontrado") -> No encontrado | M11: =_xlfn.XLOOKUP(D11,tb_contexto_precio[nombre_contexto],tb_contexto_precio[id_contexto_precio],"No encontrado") -> No encontrado | N11: =_xlfn.XLOOKUP(E11,tb_tela[nombre_tela],tb_tela[id_tela],"No encontrado") -> No encontrado | O11: =_xlfn.XLOOKUP(G11,tb_estilo[nombre_estilo],tb_estilo[id_estilo],"No encontrado") -> No encontrado | P11: =_xlfn.XLOOKUP(H11,tb_talla[talla],tb_talla[id_talla],"No encontrado") -> No encontrado | Q11: =_xlfn.XLOOKUP(I11,tb_marca[nombre_marca],tb_marca[id_marca],"No encontrado") -> No encontrado | R11: =SUMIF($C$7:$C$11,C11,$J$7:$J$11) -> 0 | S11: =_xlfn.XLOOKUP(R11,tb_rango_cantidad[min],tb_rango_cantidad[id_rango],,-1) -> #N/A
L12: =_xlfn.XLOOKUP(C12,tb_prenda[prenda],tb_prenda[id_prenda],"No encontrado") -> No encontrado | M12: =_xlfn.XLOOKUP(D12,tb_contexto_precio[nombre_contexto],tb_contexto_precio[id_contexto_precio],"No encontrado") -> No encontrado | N12: =_xlfn.XLOOKUP(E12,tb_tela[nombre_tela],tb_tela[id_tela],"No encontrado") -> No encontrado | O12: =_xlfn.XLOOKUP(G12,tb_estilo[nombre_estilo],tb_estilo[id_estilo],"No encontrado") -> No encontrado | P12: =_xlfn.XLOOKUP(H12,tb_talla[talla],tb_talla[id_talla],"No encontrado") -> No encontrado | Q12: =_xlfn.XLOOKUP(I12,tb_marca[nombre_marca],tb_marca[id_marca],"No encontrado") -> No encontrado | R12: =SUMIF($C$7:$C$11,C12,$J$7:$J$11) -> 0 | S12: =_xlfn.XLOOKUP(R12,tb_rango_cantidad[min],tb_rango_cantidad[id_rango],,-1) -> #N/A
L13: =_xlfn.XLOOKUP(C13,tb_prenda[prenda],tb_prenda[id_prenda],"No encontrado") -> No encontrado | M13: =_xlfn.XLOOKUP(D13,tb_contexto_precio[nombre_contexto],tb_contexto_precio[id_contexto_precio],"No encontrado") -> No encontrado | N13: =_xlfn.XLOOKUP(E13,tb_tela[nombre_tela],tb_tela[id_tela],"No encontrado") -> No encontrado | O13: =_xlfn.XLOOKUP(G13,tb_estilo[nombre_estilo],tb_estilo[id_estilo],"No encontrado") -> No encontrado | P13: =_xlfn.XLOOKUP(H13,tb_talla[talla],tb_talla[id_talla],"No encontrado") -> No encontrado | Q13: =_xlfn.XLOOKUP(I13,tb_marca[nombre_marca],tb_marca[id_marca],"No encontrado") -> No encontrado | R13: =SUMIF($C$7:$C$11,C13,$J$7:$J$11) -> 0 | S13: =_xlfn.XLOOKUP(R13,tb_rango_cantidad[min],tb_rango_cantidad[id_rango],,-1) -> #N/A
L14: =_xlfn.XLOOKUP(C14,tb_prenda[prenda],tb_prenda[id_prenda],"No encontrado") -> No encontrado | M14: =_xlfn.XLOOKUP(D14,tb_contexto_precio[nombre_contexto],tb_contexto_precio[id_contexto_precio],"No encontrado") -> No encontrado | N14: =_xlfn.XLOOKUP(E14,tb_tela[nombre_tela],tb_tela[id_tela],"No encontrado") -> No encontrado | O14: =_xlfn.XLOOKUP(G14,tb_estilo[nombre_estilo],tb_estilo[id_estilo],"No encontrado") -> No encontrado | P14: =_xlfn.XLOOKUP(H14,tb_talla[talla],tb_talla[id_talla],"No encontrado") -> No encontrado | Q14: =_xlfn.XLOOKUP(I14,tb_marca[nombre_marca],tb_marca[id_marca],"No encontrado") -> No encontrado | R14: =SUMIF($C$7:$C$11,C14,$J$7:$J$11) -> 0 | S14: =_xlfn.XLOOKUP(R14,tb_rango_cantidad[min],tb_rango_cantidad[id_rango],,-1) -> #N/A
L15: =_xlfn.XLOOKUP(C15,tb_prenda[prenda],tb_prenda[id_prenda],"No encontrado") -> No encontrado | M15: =_xlfn.XLOOKUP(D15,tb_contexto_precio[nombre_contexto],tb_contexto_precio[id_contexto_precio],"No encontrado") -> No encontrado | N15: =_xlfn.XLOOKUP(E15,tb_tela[nombre_tela],tb_tela[id_tela],"No encontrado") -> No encontrado | O15: =_xlfn.XLOOKUP(G15,tb_estilo[nombre_estilo],tb_estilo[id_estilo],"No encontrado") -> No encontrado | P15: =_xlfn.XLOOKUP(H15,tb_talla[talla],tb_talla[id_talla],"No encontrado") -> No encontrado | Q15: =_xlfn.XLOOKUP(I15,tb_marca[nombre_marca],tb_marca[id_marca],"No encontrado") -> No encontrado | R15: =SUMIF($C$7:$C$11,C15,$J$7:$J$11) -> 0 | S15: =_xlfn.XLOOKUP(R15,tb_rango_cantidad[min],tb_rango_cantidad[id_rango],,-1) -> #N/A
L16: =_xlfn.XLOOKUP(C16,tb_prenda[prenda],tb_prenda[id_prenda],"No encontrado") -> No encontrado | M16: =_xlfn.XLOOKUP(D16,tb_contexto_precio[nombre_contexto],tb_contexto_precio[id_contexto_precio],"No encontrado") -> No encontrado | N16: =_xlfn.XLOOKUP(E16,tb_tela[nombre_tela],tb_tela[id_tela],"No encontrado") -> No encontrado | O16: =_xlfn.XLOOKUP(G16,tb_estilo[nombre_estilo],tb_estilo[id_estilo],"No encontrado") -> No encontrado | P16: =_xlfn.XLOOKUP(H16,tb_talla[talla],tb_talla[id_talla],"No encontrado") -> No encontrado | Q16: =_xlfn.XLOOKUP(I16,tb_marca[nombre_marca],tb_marca[id_marca],"No encontrado") -> No encontrado | R16: =SUMIF($C$7:$C$11,C16,$J$7:$J$11) -> 0 | S16: =_xlfn.XLOOKUP(R16,tb_rango_cantidad[min],tb_rango_cantidad[id_rango],,-1) -> #N/A
L17: =_xlfn.XLOOKUP(C17,tb_prenda[prenda],tb_prenda[id_prenda],"No encontrado") -> No encontrado | M17: =_xlfn.XLOOKUP(D17,tb_contexto_precio[nombre_contexto],tb_contexto_precio[id_contexto_precio],"No encontrado") -> No encontrado | N17: =_xlfn.XLOOKUP(E17,tb_tela[nombre_tela],tb_tela[id_tela],"No encontrado") -> No encontrado | O17: =_xlfn.XLOOKUP(G17,tb_estilo[nombre_estilo],tb_estilo[id_estilo],"No encontrado") -> No encontrado | P17: =_xlfn.XLOOKUP(H17,tb_talla[talla],tb_talla[id_talla],"No encontrado") -> No encontrado | Q17: =_xlfn.XLOOKUP(I17,tb_marca[nombre_marca],tb_marca[id_marca],"No encontrado") -> No encontrado | R17: =SUMIF($C$7:$C$11,C17,$J$7:$J$11) -> 0 | S17: =_xlfn.XLOOKUP(R17,tb_rango_cantidad[min],tb_rango_cantidad[id_rango],,-1) -> #N/A
L18: =_xlfn.XLOOKUP(C18,tb_prenda[prenda],tb_prenda[id_prenda],"No encontrado") -> No encontrado | M18: =_xlfn.XLOOKUP(D18,tb_contexto_precio[nombre_contexto],tb_contexto_precio[id_contexto_precio],"No encontrado") -> No encontrado | N18: =_xlfn.XLOOKUP(E18,tb_tela[nombre_tela],tb_tela[id_tela],"No encontrado") -> No encontrado | O18: =_xlfn.XLOOKUP(G18,tb_estilo[nombre_estilo],tb_estilo[id_estilo],"No encontrado") -> No encontrado | P18: =_xlfn.XLOOKUP(H18,tb_talla[talla],tb_talla[id_talla],"No encontrado") -> No encontrado | Q18: =_xlfn.XLOOKUP(I18,tb_marca[nombre_marca],tb_marca[id_marca],"No encontrado") -> No encontrado | R18: =SUMIF($C$7:$C$11,C18,$J$7:$J$11) -> 0 | S18: =_xlfn.XLOOKUP(R18,tb_rango_cantidad[min],tb_rango_cantidad[id_rango],,-1) -> #N/A
L19: =_xlfn.XLOOKUP(C19,tb_prenda[prenda],tb_prenda[id_prenda],"No encontrado") -> No encontrado | M19: =_xlfn.XLOOKUP(D19,tb_contexto_precio[nombre_contexto],tb_contexto_precio[id_contexto_precio],"No encontrado") -> No encontrado | N19: =_xlfn.XLOOKUP(E19,tb_tela[nombre_tela],tb_tela[id_tela],"No encontrado") -> No encontrado | O19: =_xlfn.XLOOKUP(G19,tb_estilo[nombre_estilo],tb_estilo[id_estilo],"No encontrado") -> No encontrado | P19: =_xlfn.XLOOKUP(H19,tb_talla[talla],tb_talla[id_talla],"No encontrado") -> No encontrado | Q19: =_xlfn.XLOOKUP(I19,tb_marca[nombre_marca],tb_marca[id_marca],"No encontrado") -> No encontrado | R19: =SUMIF($C$7:$C$11,C19,$J$7:$J$11) -> 0 | S19: =_xlfn.XLOOKUP(R19,tb_rango_cantidad[min],tb_rango_cantidad[id_rango],,-1) -> #N/A
L20: =_xlfn.XLOOKUP(C20,tb_prenda[prenda],tb_prenda[id_prenda],"No encontrado") -> No encontrado | M20: =_xlfn.XLOOKUP(D20,tb_contexto_precio[nombre_contexto],tb_contexto_precio[id_contexto_precio],"No encontrado") -> No encontrado | N20: =_xlfn.XLOOKUP(E20,tb_tela[nombre_tela],tb_tela[id_tela],"No encontrado") -> No encontrado | O20: =_xlfn.XLOOKUP(G20,tb_estilo[nombre_estilo],tb_estilo[id_estilo],"No encontrado") -> No encontrado | P20: =_xlfn.XLOOKUP(H20,tb_talla[talla],tb_talla[id_talla],"No encontrado") -> No encontrado | Q20: =_xlfn.XLOOKUP(I20,tb_marca[nombre_marca],tb_marca[id_marca],"No encontrado") -> No encontrado | R20: =SUMIF($C$7:$C$11,C20,$J$7:$J$11) -> 0 | S20: =_xlfn.XLOOKUP(R20,tb_rango_cantidad[min],tb_rango_cantidad[id_rango],,-1) -> #N/A
L21: =_xlfn.XLOOKUP(C21,tb_prenda[prenda],tb_prenda[id_prenda],"No encontrado") -> No encontrado | M21: =_xlfn.XLOOKUP(D21,tb_contexto_precio[nombre_contexto],tb_contexto_precio[id_contexto_precio],"No encontrado") -> No encontrado | N21: =_xlfn.XLOOKUP(E21,tb_tela[nombre_tela],tb_tela[id_tela],"No encontrado") -> No encontrado | O21: =_xlfn.XLOOKUP(G21,tb_estilo[nombre_estilo],tb_estilo[id_estilo],"No encontrado") -> No encontrado | P21: =_xlfn.XLOOKUP(H21,tb_talla[talla],tb_talla[id_talla],"No encontrado") -> No encontrado | Q21: =_xlfn.XLOOKUP(I21,tb_marca[nombre_marca],tb_marca[id_marca],"No encontrado") -> No encontrado | R21: =SUMIF($C$7:$C$11,C21,$J$7:$J$11) -> 0 | S21: =_xlfn.XLOOKUP(R21,tb_rango_cantidad[min],tb_rango_cantidad[id_rango],,-1) -> #N/A
... L26: =_xlfn.XLOOKUP(C26,tb_prenda[prenda],tb_prenda[id_prenda],"No encontrado") -> No encontrado | M26: =_xlfn.XLOOKUP(D26,tb_contexto_precio[nombre_contexto],tb_contexto_precio[id_contexto_precio],"No encontrado") -> No encontrado | N26: =_xlfn.XLOOKUP(E26,tb_tela[nombre_tela],tb_tela[id_tela],"No encontrado") -> No encontrado | O26: =_xlfn.XLOOKUP(G26,tb_estilo[nombre_estilo],tb_estilo[id_estilo],"No encontrado") -> No encontrado | P26: =_xlfn.XLOOKUP(H26,tb_talla[talla],tb_talla[id_talla],"No encontrado") -> No encontrado | Q26: =_xlfn.XLOOKUP(I26,tb_marca[nombre_marca],tb_marca[id_marca],"No encontrado") -> No encontrado | R26: =SUMIF($C$7:$C$11,C26,$J$7:$J$11) -> 0 | S26: =_xlfn.XLOOKUP(R26,tb_rango_cantidad[min],tb_rango_cantidad[id_rango],,-1) -> #N/A
Y27: Total | Z27: =SUM(Z7:Z11) -> 161
