Workbook
Name Lista_Colores1: _xlfn.ANCHORARRAY(Aux!$D$4)
Name Lista_Colores10: _xlfn.ANCHORARRAY(Aux!$D$125)
Name Lista_Colores11: _xlfn.ANCHORARRAY(Aux!$D$138)
Name Lista_Colores12: _xlfn.ANCHORARRAY(Aux!$D$151)
Name Lista_Colores13: _xlfn.ANCHORARRAY(Aux!$D$164)
Name Lista_Colores14: _xlfn.ANCHORARRAY(Aux!$D$177)
Name Lista_Colores15: _xlfn.ANCHORARRAY(Aux!$D$190)
Name Lista_Colores16: _xlfn.ANCHORARRAY(Aux!$D$203)
Name Lista_Colores17: _xlfn.ANCHORARRAY(Aux!$D$216)
Name Lista_Colores18: _xlfn.ANCHORARRAY(Aux!$D$229)
Name Lista_Colores19: _xlfn.ANCHORARRAY(Aux!$D$242)
Name Lista_Colores2: _xlfn.ANCHORARRAY(Aux!$D$17)
Name Lista_Colores20: _xlfn.ANCHORARRAY(Aux!$D$255)
Name Lista_Colores3: _xlfn.ANCHORARRAY(Aux!$D$31)
Name Lista_Colores4: _xlfn.ANCHORARRAY(Aux!$D$45)
Name Lista_Colores5: _xlfn.ANCHORARRAY(Aux!$D$59)
Name Lista_Colores6: _xlfn.ANCHORARRAY(Aux!$D$72)
Name Lista_Colores7: _xlfn.ANCHORARRAY(Aux!$D$85)
Name Lista_Colores8: _xlfn.ANCHORARRAY(Aux!$D$98)
Name Lista_Colores9: _xlfn.ANCHORARRAY(Aux!$D$112)
Name Lista_Estilos1: _xlfn.ANCHORARRAY(Aux!$H$4)
Name Lista_Estilos10: _xlfn.ANCHORARRAY(Aux!$H$40)
Name Lista_Estilos11: _xlfn.ANCHORARRAY(Aux!$H$44)
Name Lista_Estilos12: _xlfn.ANCHORARRAY(Aux!$H$48)
Name Lista_Estilos13: _xlfn.ANCHORARRAY(Aux!$H$52)
Name Lista_Estilos14: _xlfn.ANCHORARRAY(Aux!$H$56)
Name Lista_Estilos15: _xlfn.ANCHORARRAY(Aux!$H$60)
Name Lista_Estilos16: _xlfn.ANCHORARRAY(Aux!$H$64)
Name Lista_Estilos17: _xlfn.ANCHORARRAY(Aux!$H$68)
Name Lista_Estilos18: _xlfn.ANCHORARRAY(Aux!$H$72)
Name Lista_Estilos19: _xlfn.ANCHORARRAY(Aux!$H$76)
Name Lista_Estilos2: _xlfn.ANCHORARRAY(Aux!$H$8)
Name Lista_Estilos20: _xlfn.ANCHORARRAY(Aux!$H$80)
Name Lista_Estilos3: _xlfn.ANCHORARRAY(Aux!$H$12)
Name Lista_Estilos4: _xlfn.ANCHORARRAY(Aux!$H$16)
Name Lista_Estilos5: _xlfn.ANCHORARRAY(Aux!$H$20)
Name Lista_Estilos6: _xlfn.ANCHORARRAY(Aux!$H$24)
Name Lista_Estilos7: _xlfn.ANCHORARRAY(Aux!$H$28)
Name Lista_Estilos8: _xlfn.ANCHORARRAY(Aux!$H$32)
Name Lista_Estilos9: _xlfn.ANCHORARRAY(Aux!$H$36)
Name Lista_Marca1: _xlfn.ANCHORARRAY(Aux!$F$4)
Name Lista_Marca10: _xlfn.ANCHORARRAY(Aux!$F$31)
Name Lista_Marca11: _xlfn.ANCHORARRAY(Aux!$F$34)
Name Lista_Marca12: _xlfn.ANCHORARRAY(Aux!$F$37)
Name Lista_Marca13: _xlfn.ANCHORARRAY(Aux!$F$40)
Name Lista_Marca14: _xlfn.ANCHORARRAY(Aux!$F$43)
Name Lista_Marca15: _xlfn.ANCHORARRAY(Aux!$F$46)
Name Lista_Marca16: _xlfn.ANCHORARRAY(Aux!$F$49)
Name Lista_Marca17: _xlfn.ANCHORARRAY(Aux!$F$52)
Name Lista_Marca18: _xlfn.ANCHORARRAY(Aux!$F$55)
Name Lista_Marca19: _xlfn.ANCHORARRAY(Aux!$F$58)
Name Lista_Marca2: _xlfn.ANCHORARRAY(Aux!$F$7)
Name Lista_Marca20: _xlfn.ANCHORARRAY(Aux!$F$61)
Name Lista_Marca3: _xlfn.ANCHORARRAY(Aux!$F$10)
Name Lista_Marca4: _xlfn.ANCHORARRAY(Aux!$F$13)
Name Lista_Marca5: _xlfn.ANCHORARRAY(Aux!$F$16)
Name Lista_Marca6: _xlfn.ANCHORARRAY(Aux!$F$19)
Name Lista_Marca7: _xlfn.ANCHORARRAY(Aux!$F$22)
Name Lista_Marca8: _xlfn.ANCHORARRAY(Aux!$F$25)
Name Lista_Marca9: _xlfn.ANCHORARRAY(Aux!$F$28)

Sheet Cotizador
E5: Prenda | F5: Polo | G5: =_xlfn.XLOOKUP(F5,tb_prenda[prenda],tb_prenda[id_prenda],"No encontrado") -> 1 | N5: DESCRIPCIÓN DE PRODUCTO | O5: PRECIO U. | P5: CANTIDAD | Q5: IMPORTE
E6: Contexto | F6: Navidad y Año Nuevo | G6: =_xlfn.XLOOKUP(F6,tb_contexto_precio[nombre_contexto],tb_contexto_precio[id_contexto_precio],"No encontrado") -> 2 | N6: BOXER CALVIN KLEIN TALLA M | O6: 18 | P6: 2 | Q6: =O6*P6 -> 36
N7: POLERA DE FRANELA COLOR NEGRO ESTILO CAPUCHA + BOLSILLO TALLA T4 | O7: 40 | P7: 12 | Q7: =O7*P7 -> 480
E8: Tela | F8: Alta calidad | G8: =_xlfn.XLOOKUP(F8,tb_tela[nombre_tela],tb_tela[id_tela],"No encontrado") -> 1 | I8: id_tela_prenda | J8: {=_xlfn.XLOOKUP(1,(tb_tela_prenda[id_prenda]=G5)*(tb_tela_prenda[id_tela]=G8),tb_tela_prenda[id_tela_prenda])} -> 1 | P8: TOTAL
E9: Color | F9: Blanco
E11: Estilo | F11: No necesario | G11: =_xlfn.XLOOKUP(F11,tb_estilo[nombre_estilo],tb_estilo[id_estilo],"No encontrado") -> No encontrado | I11: id_estilo_talla | J11: {=_xlfn.XLOOKUP(1,(tb_estilo_talla[id_estilo]=G11)*(tb_estilo_talla[id_talla]=G12),tb_estilo_talla[id_estilo_talla])} -> #N/A
E12: Talla | F12: 4 - 7 m | G12: =_xlfn.XLOOKUP(F12,tb_talla[talla],tb_talla[id_talla],"No encontrado") -> 14
E14: Marca | F14: No necesario | G14: =_xlfn.XLOOKUP(F14,tb_marca[nombre_marca],tb_marca[id_marca],"No encontrado") -> No encontrado
E16: Cantidad | F16: 1 | G16: =_xlfn.XLOOKUP(F16,tb_rango_cantidad[min],tb_rango_cantidad[id_rango],,-1) -> 1
E17: Precio Unitario | F17: {=IF(G5=1, _xlfn.XLOOKUP(1, (tb_precio_polos[id_contexto_precio]=G6)* (tb_precio_polos[id_tela]=J8)* (tb_precio_polos[id_talla]=G12)* (tb_precio_polos[id_rango]=G16), tb_precio_polos[precio] ), IF(G5=2, _xlfn.XLOOKUP(1, (tb_precio_poleras[id_contexto_precio]=G6)* (tb_precio_poleras[id_tela]=J8)* (tb_precio_poleras[id_talla]=J11)* (tb_precio_poleras[id_rango]=G16), tb_precio_poleras[precio] ), IF(G5=3, _xlfn.XLOOKUP(1, (tb_precio_body[id_contexto_precio]=G6)* (tb_precio_body[id_talla]=G12)* (tb_precio_body[id_rango]=G16), tb_precio_body[precio] ), IF(G5=4, _xlfn.XLOOKUP(1, (tb_precio_boxer[id_contexto_precio]=G6)* (tb_precio_boxer[id_marca]=G14)* (tb_precio_boxer[id_talla]=G12), tb_precio_boxer[precio] ), "" ))))} -> #N/A
E18: Total | F18: =F16*F17 -> #N/A
F21: =UPPER(IF(G5=1,F5&" de "&F8&" "&F9& " corte "&F11&" "&F12,IF(G5=2,F5&" de "&F8&" "&F9& " de "&F11&" "&F12,IF(G5=3,F5&" "&F12,IF(G5=4,F5&" "&F14&" "&F12," "))))) -> POLO DE ALTA CALIDAD BLANCO CORTE NO NECESARIO 4 - 7 M

Sheet Rango
A1: id_rango | B1: descripcion | C1: min | D1: max
A2: 1 | B2: Unidad | C2: 1 | D2: 5
A3: 2 | B3: Media docena | C3: 6 | D3: 11
A4: 3 | B4: Docena o más | C4: 12 | D4: 999

Sheet Talla-Prenda
A1: id_talla_prenda | B1: id_talla | C1: id_prenda
A2: 1 | B2: 1 | C2: 1
A3: 2 | B3: 2 | C3: 1
A4: 3 | B4: 3 | C4: 1
A5: 4 | B5: 4 | C5: 1
A6: 5 | B6: 5 | C6: 1
A7: 6 | B7: 6 | C7: 1
A8: 7 | B8: 7 | C8: 1
A9: 8 | B9: 8 | C9: 1
A10: 9 | B10: 9 | C10: 1
A11: 10 | B11: 10 | C11: 1
A12: 11 | B12: 11 | C12: 1
A13: 12 | B13: 12 | C13: 1
... A32: 31 | B32: 11 | C32: 4

Sheet Tela-Color
A1: id_tela_color | B1: id_tela | C1: id_color
A2: 1 | B2: 1 | C2: 1
A3: 2 | B3: 1 | C3: 2
A4: 3 | B4: 1 | C4: 3
A5: 4 | B5: 1 | C5: 4
A6: 5 | B6: 1 | C6: 5
A7: 6 | B7: 1 | C7: 6
A8: 7 | B8: 1 | C8: 7
A9: 8 | B9: 1 | C9: 8
A10: 9 | B10: 1 | C10: 9
A11: 10 | B11: 1 | C11: 10
A12: 11 | B12: 1 | C12: 11
A13: 12 | B13: 1 | C13: 12
... A25: 24 | B25: 4 | C25: 13

Sheet Estilo-Talla
A1: id_estilo_talla | B1: id_estilo | C1: id_talla | D1: id_prenda
A2: 1 | B2: 1 | C2: 1 | D2: 1
A3: 2 | B3: 1 | C3: 2 | D3: 1
A4: 3 | B4: 1 | C4: 3 | D4: 1
A5: 4 | B5: 1 | C5: 4 | D5: 1
A6: 5 | B6: 1 | C6: 5 | D6: 1
A7: 6 | B7: 1 | C7: 6 | D7: 1
A8: 7 | B8: 2 | C8: 7 | D8: 1
A9: 8 | B9: 2 | C9: 8 | D9: 1
A10: 9 | B10: 2 | C10: 9 | D10: 1
A11: 10 | B11: 2 | C11: 10 | D11: 1
A12: 11 | B12: 2 | C12: 11 | D12: 1
A13: 12 | B13: 2 | C13: 12 | D13: 1
... A41: 40 | B41: 5 | C41: 12 | D41: 2

Sheet Tela-Prenda
A1: id_tela_prenda | B1: id_tela | C1: id_prenda
A2: 1 | B2: 1 | C2: 1
A3: 2 | B3: 2 | C3: 1
A4: 3 | B4: 3 | C4: 2
A5: 4 | B5: 4 | C5: 2
A6: 5 | B6: 1 | C6: 3

Sheet Precios-Polos
A1: id_precio_polo | B1: id_contexto_precio | C1: id_tela | D1: id_talla | E1: id_rango | F1: precio
A2: 1 | B2: 1 | C2: 1 | D2: 1 | E2: 1 | F2: 33
A3: 2 | B3: 1 | C3: 1 | D3: 1 | E3: 2 | F3: 28
A4: 3 | B4: 1 | C4: 1 | D4: 1 | E4: 3 | F4: 23
A5: 4 | B5: 1 | C5: 1 | D5: 2 | E5: 1 | F5: 33
A6: 5 | B6: 1 | C6: 1 | D6: 2 | E6: 2 | F6: 28
A7: 6 | B7: 1 | C7: 1 | D7: 2 | E7: 3 | F7: 23
A8: 7 | B8: 1 | C8: 1 | D8: 3 | E8: 1 | F8: 33
A9: 8 | B9: 1 | C9: 1 | D9: 3 | E9: 2 | F9: 28
A10: 9 | B10: 1 | C10: 1 | D10: 3 | E10: 3 | F10: 23
A11: 10 | B11: 1 | C11: 1 | D11: 4 | E11: 1 | F11: 33
A12: 11 | B12: 1 | C12: 1 | D12: 4 | E12: 2 | F12: 28
A13: 12 | B13: 1 | C13: 1 | D13: 4 | E13: 3 | F13: 23
... A217: 216 | B217: 3 | C217: 2 | D217: 12 | E217: 3 | F217: 26

Sheet Precio-Poleras
A1: id_precio_polera | B1: id_contexto_precio | C1: id_tela | D1: id_estilo | E1: id_talla | F1: id_rango | G1: precio
A2: 1 | B2: 1 | C2: 3 | D2: 4 | E2: 1 | F2: 1 | G2: 50
A3: 2 | B3: 1 | C3: 3 | D3: 4 | E3: 1 | F3: 2 | G3: 45
A4: 3 | B4: 1 | C4: 3 | D4: 4 | E4: 1 | F4: 3 | G4: 40
A5: 4 | B5: 1 | C5: 3 | D5: 4 | E5: 2 | F5: 1 | G5: 50
A6: 5 | B6: 1 | C6: 3 | D6: 4 | E6: 2 | F6: 2 | G6: 45
A7: 6 | B7: 1 | C7: 3 | D7: 4 | E7: 2 | F7: 3 | G7: 40
A8: 7 | B8: 1 | C8: 3 | D8: 4 | E8: 3 | F8: 1 | G8: 50
A9: 8 | B9: 1 | C9: 3 | D9: 4 | E9: 3 | F9: 2 | G9: 45
A10: 9 | B10: 1 | C10: 3 | D10: 4 | E10: 3 | F10: 3 | G10: 40
A11: 10 | B11: 1 | C11: 3 | D11: 4 | E11: 4 | F11: 1 | G11: 50
A12: 11 | B12: 1 | C12: 3 | D12: 4 | E12: 4 | F12: 2 | G12: 45
A13: 12 | B13: 1 | C13: 3 | D13: 4 | E13: 4 | F13: 3 | G13: 40
... A289: 288 | B289: 2 | C289: 4 | D289: 5 | E289: 12 | F289: 3 | G289: 40

Sheet Precio-Boxers
A1: id_precio_boxer | B1: id_contexto_precio | C1: id_marca | D1: id_talla | E1: precio
A2: 1 | B2: 1 | C2: 1 | D2: 8 | E2: 35
A3: 2 | B3: 1 | C3: 1 | D3: 9 | E3: 35
A4: 3 | B4: 1 | C4: 1 | D4: 10 | E4: 35
A5: 4 | B5: 1 | C5: 1 | D5: 11 | E5: 38
A6: 5 | B6: 1 | C6: 2 | D6: 8 | E6: 25
A7: 6 | B7: 1 | C7: 2 | D7: 9 | E7: 25
A8: 7 | B8: 1 | C8: 2 | D8: 10 | E8: 25
A9: 8 | B9: 1 | C9: 2 | D9: 11 | E9: 28
A10: 9 | B10: 2 | C10: 1 | D10: 8 | E10: 30
A11: 10 | B11: 2 | C11: 1 | D11: 9 | E11: 30
A12: 11 | B12: 2 | C12: 1 | D12: 10 | E12: 30
A13: 12 | B13: 2 | C13: 1 | D13: 11 | E13: 33
... A17: 16 | B17: 2 | C17: 2 | D17: 11 | E17: 23

Sheet Precio-Bodys
A1: id_precio_body | B1: id_contexto_precio | C1: id_talla | D1: id_rango | E1: precio
A2: 1 | B2: 1 | C2: 13 | D2: 1 | E2: 30
A3: 2 | B3: 1 | C3: 13 | D3: 2 | E3: 25
A4: 3 | B4: 1 | C4: 13 | D4: 3 | E4: 23
A5: 4 | B5: 1 | C5: 14 | D5: 1 | E5: 30
A6: 5 | B6: 1 | C6: 14 | D6: 2 | E6: 25
A7: 6 | B7: 1 | C7: 14 | D7: 3 | E7: 23
A8: 7 | B8: 1 | C8: 15 | D8: 1 | E8: 30
A9: 8 | B9: 1 | C9: 15 | D9: 2 | E9: 25
A10: 9 | B10: 1 | C10: 15 | D10: 3 | E10: 23
A11: 10 | B11: 2 | C11: 13 | D11: 1 | E11: 23
A12: 11 | B12: 2 | C12: 13 | D12: 2 | E12: 20
A13: 12 | B13: 2 | C13: 13 | D13: 3 | E13: 18
... A19: 18 | B19: 2 | C19: 15 | D19: 3 | E19: 18

Sheet Prenda
A1: id_prenda | B1: prenda
A2: 1 | B2: Polo
A3: 2 | B3: Polera
A4: 3 | B4: Body
A5: 4 | B5: Boxer

Sheet Contexto
A1: id_contexto_precio | B1: nombre_contexto | C1: tipo_contexto | D1: estado
A2: 1 | B2: Precio General | C2: Base | D2: Activo
A3: 2 | B3: Navidad y Año Nuevo | C3: Campaña | D3: Activo
A4: 3 | B4: Graduación | C4: Campaña | D4: Activo
A5: 4 | B5: Verano | C5: Campaña | D5: Planificado
A6: 5 | B6: San Valentín | C6: Campaña | D6: Planificado
A7: 6 | B7: Día de la Madre | C7: Campaña | D7: Histórico
A8: 7 | B8: Día de la Educación Inicial | C8: Campaña | D8: Histórico
A9: 8 | B9: Día del Padre | C9: Campaña | D9: Histórico

Sheet Color
A1: id_color | B1: color
A2: 1 | B2: Amarillo
A3: 2 | B3: Anaranjado
A4: 3 | B4: Azul
A5: 4 | B5: Blanco
A6: 5 | B6: Celeste Bebé
A7: 6 | B7: Fucsia
A8: 7 | B8: Lila
A9: 8 | B9: Negro
A10: 9 | B10: Rojo
A11: 10 | B11: Rosado
A12: 11 | B12: Turqueza
A13: 12 | B13: Verde
A14: 13 | B14: Melange

Sheet Talla
A1: id_talla | B1: talla | C1: tipo
A2: 1 | B2: T2 | C2: Niño
A3: 2 | B3: T4 | C3: Niño
A4: 3 | B4: T6 | C4: Niño
A5: 4 | B5: T8 | C5: Niño
A6: 5 | B6: T10 | C6: Niño
A7: 6 | B7: T12 | C7: Niño
A8: 7 | B8: T14 | C8: Adulto
A9: 8 | B9: S | C9: Adulto
A10: 9 | B10: M | C10: Adulto
A11: 10 | B11: L | C11: Adulto
A12: 11 | B12: XL | C12: Adulto
A13: 12 | B13: XXL | C13: Adulto
... A16: 15 | B16: 8 - 11 m | C16: Bebé

Sheet Tela
A1: id_tela | B1: nombre_tela
A2: 1 | B2: Alta calidad
A3: 2 | B3: Calidad intermedia
A4: 3 | B4: Franela
A5: 4 | B5: Policoton

Sheet Estilo
A1: id_estilo | B1: nombre_estilo | C1: id_prenda
A2: 1 | B2: Niño | C2: 1
A3: 2 | B3: Recto | C3: 1
A4: 3 | B4: Princesa | C4: 1
A5: 4 | B5: Capucha + bolsillo | C5: 2
A6: 5 | B6: Cuello redondo | C6: 2

Sheet Marca
A1: id_marca | B1: nombre_marca | C1: id_prenda
A2: 1 | B2: Boston | C2: 4
A3: 2 | B3: Calvin Klein | C3: 4

Sheet Aux
B2: Lista_Telas# | D2: Lista_Colores# | F2: Lista_Marca# | H2: Lista_Estilos# | J2: Lista_Tallas#
B4: {=_xlfn._xlws.FILTER( tb_tela[nombre_tela], ISNUMBER( MATCH( tb_tela[id_tela], _xlfn._xlws.FILTER( tb_tela_prenda[id_tela], tb_tela_prenda[id_prenda]=Cotiz!L7 ), 0 ) ), "No necesario" )} -> Alta calidad | D4: {=_xlfn._xlws.FILTER( tb_color[color], ISNUMBER( MATCH( tb_color[id_color], _xlfn._xlws.FILTER( tb_tela_color[id_color], tb_tela_color[id_tela]=Cotiz!N7 ), 0 ) ),"No necesario" )} -> Amarillo | F4: {=_xlfn._xlws.FILTER( tb_marca[nombre_marca], tb_marca[id_prenda]=Cotiz!L7, "No necesario" )} -> No necesario | H4: {=_xlfn._xlws.FILTER(tb_estilo[nombre_estilo], tb_estilo[id_prenda]=Cotiz!L7, "No necesario")} -> Niño | J4: {=IF( OR(Cotiz!L7=3,Cotiz!L7=4), _xlfn._xlws.FILTER( tb_talla[talla], ISNUMBER( MATCH( tb_talla[id_talla], _xlfn._xlws.FILTER( tb_talla_prenda[id_talla], tb_talla_prenda[id_prenda]=Cotiz!L7 ), 0 ) ), "No hay tallas" ), _xlfn._xlws.FILTER( tb_talla[talla], ISNUMBER( MATCH( tb_talla[id_talla], _xlfn._xlws.FILTER( tb_estilo_talla[id_talla], (tb_estilo_talla[id_prenda]=Cotiz!L7)* (tb_estilo_talla[id_estilo]=Cotiz!O7) ), 0 ) ), "No hay tallas" ) )} -> T14
B5: Calidad intermedia | D5: Blanco | H5: Recto | J5: S
D6: Negro | H6: Princesa | J6: M
B7: {=_xlfn._xlws.FILTER( tb_tela[nombre_tela], ISNUMBER( MATCH( tb_tela[id_tela], _xlfn._xlws.FILTER( tb_tela_prenda[id_tela], tb_tela_prenda[id_prenda]=Cotiz!L8 ), 0 ) ), "No necesario" )} -> Alta calidad | D7: Rojo | F7: {=_xlfn._xlws.FILTER( tb_marca[nombre_marca], tb_marca[id_prenda]=Cotiz!L8, "No necesario" )} -> No necesario | J7: L
B8: Calidad intermedia | D8: Rosado | H8: {=_xlfn._xlws.FILTER(tb_estilo[nombre_estilo], tb_estilo[id_prenda]=Cotiz!L8, "No necesario")} -> Niño | J8: XL
D9: Verde | H9: Recto | J9: XXL
B10: {=_xlfn._xlws.FILTER( tb_tela[nombre_tela], ISNUMBER( MATCH( tb_tela[id_tela], _xlfn._xlws.FILTER( tb_tela_prenda[id_tela], tb_tela_prenda[id_prenda]=Cotiz!L9 ), 0 ) ), "No necesario" )} -> Alta calidad | F10: {=_xlfn._xlws.FILTER( tb_marca[nombre_marca], tb_marca[id_prenda]=Cotiz!L9, "No necesario" )} -> No necesario | H10: Princesa
B11: Calidad intermedia
H12: {=_xlfn._xlws.FILTER(tb_estilo[nombre_estilo], tb_estilo[id_prenda]=Cotiz!L9, "No necesario")} -> Niño
B13: {=_xlfn._xlws.FILTER( tb_tela[nombre_tela], ISNUMBER( MATCH( tb_tela[id_tela], _xlfn._xlws.FILTER( tb_tela_prenda[id_tela], tb_tela_prenda[id_prenda]=Cotiz!L10 ), 0 ) ), "No necesario" )} -> No necesario | F13: {=_xlfn._xlws.FILTER( tb_marca[nombre_marca], tb_marca[id_prenda]=Cotiz!L10, "No necesario" )} -> No necesario | H13: Recto
H14: Princesa
B16: {=_xlfn._xlws.FILTER( tb_tela[nombre_tela], ISNUMBER( MATCH( tb_tela[id_tela], _xlfn._xlws.FILTER( tb_tela_prenda[id_tela], tb_tela_prenda[id_prenda]=Cotiz!L11 ), 0 ) ), "No necesario" )} -> No necesario | F16: {=_xlfn._xlws.FILTER( tb_marca[nombre_marca], tb_marca[id_prenda]=Cotiz!L11, "No necesario" )} -> No necesario | H16: {=_xlfn._xlws.FILTER(tb_estilo[nombre_estilo], tb_estilo[id_prenda]=Cotiz!L10, "No necesario")} -> No necesario
D17: {=_xlfn._xlws.FILTER( tb_color[color], ISNUMBER( MATCH( tb_color[id_color], _xlfn._xlws.FILTER( tb_tela_color[id_color], tb_tela_color[id_tela]=Cotiz!N8 ), 0 ) ),"No necesario" )} -> Amarillo | J17: {=IF( OR(Cotiz!L8=3,Cotiz!L8=4), _xlfn._xlws.FILTER( tb_talla[talla], ISNUMBER( MATCH( tb_talla[id_talla], _xlfn._xlws.FILTER( tb_talla_prenda[id_talla], tb_talla_prenda[id_prenda]=Cotiz!L8 ), 0 ) ), "No hay tallas" ), _xlfn._xlws.FILTER( tb_talla[talla], ISNUMBER( MATCH( tb_talla[id_talla], _xlfn._xlws.FILTER( tb_estilo_talla[id_talla], (tb_estilo_talla[id_prenda]=Cotiz!L8)* (tb_estilo_talla[id_estilo]=Cotiz!O8) ), 0 ) ), "No hay tallas" ) )} -> T14
D18: Anaranjado | J18: S
B19: {=_xlfn._xlws.FILTER( tb_tela[nombre_tela], ISNUMBER( MATCH( tb_tela[id_tela], _xlfn._xlws.FILTER( tb_tela_prenda[id_tela], tb_tela_prenda[id_prenda]=Cotiz!L12 ), 0 ) ), "No necesario" )} -> No necesario | D19: Azul | F19: {=_xlfn._xlws.FILTER( tb_marca[nombre_marca], tb_marca[id_prenda]=Cotiz!L12, "No necesario" )} -> No necesario | J19: M
D20: Blanco | H20: {=_xlfn._xlws.FILTER(tb_estilo[nombre_estilo], tb_estilo[id_prenda]=Cotiz!L11, "No necesario")} -> No necesario | J20: L
D21: Celeste Bebé | J21: XL
B22: {=_xlfn._xlws.FILTER( tb_tela[nombre_tela], ISNUMBER( MATCH( tb_tela[id_tela], _xlfn._xlws.FILTER( tb_tela_prenda[id_tela], tb_tela_prenda[id_prenda]=Cotiz!L13 ), 0 ) ), "No necesario" )} -> No necesario | D22: Fucsia | F22: {=_xlfn._xlws.FILTER( tb_marca[nombre_marca], tb_marca[id_prenda]=Cotiz!L13, "No necesario" )} -> No necesario | J22: XXL
D23: Lila
D24: Negro | H24: {=_xlfn._xlws.FILTER(tb_estilo[nombre_estilo], tb_estilo[id_prenda]=Cotiz!L12, "No necesario")} -> No necesario
B25: {=_xlfn._xlws.FILTER( tb_tela[nombre_tela], ISNUMBER( MATCH( tb_tela[id_tela], _xlfn._xlws.FILTER( tb_tela_prenda[id_tela], tb_tela_prenda[id_prenda]=Cotiz!L14 ), 0 ) ), "No necesario" )} -> No necesario | D25: Rojo | F25: {=_xlfn._xlws.FILTER( tb_marca[nombre_marca], tb_marca[id_prenda]=Cotiz!L14, "No necesario" )} -> No necesario
D26: Rosado
D27: Turqueza
B28: {=_xlfn._xlws.FILTER( tb_tela[nombre_tela], ISNUMBER( MATCH( tb_tela[id_tela], _xlfn._xlws.FILTER( tb_tela_prenda[id_tela], tb_tela_prenda[id_prenda]=Cotiz!L15 ), 0 ) ), "No necesario" )} -> No necesario | D28: Verde | F28: {=_xlfn._xlws.FILTER( tb_marca[nombre_marca], tb_marca[id_prenda]=Cotiz!L15, "No necesario" )} -> No necesario | H28: {=_xlfn._xlws.FILTER(tb_estilo[nombre_estilo], tb_estilo[id_prenda]=Cotiz!L13, "No necesario")} -> No necesario
J30: {=IF( OR(Cotiz!L9=3,Cotiz!L9=4), _xlfn._xlws.FILTER( tb_talla[talla], ISNUMBER( MATCH( tb_talla[id_talla], _xlfn._xlws.FILTER( tb_talla_prenda[id_talla], tb_talla_prenda[id_prenda]=Cotiz!L9 ), 0 ) ), "No hay tallas" ), _xlfn._xlws.FILTER( tb_talla[talla], ISNUMBER( MATCH( tb_talla[id_talla], _xlfn._xlws.FILTER( tb_estilo_talla[id_talla], (tb_estilo_talla[id_prenda]=Cotiz!L9)* (tb_estilo_talla[id_estilo]=Cotiz!O9) ), 0 ) ), "No hay tallas" ) )} -> T14
B31: {=_xlfn._xlws.FILTER( tb_tela[nombre_tela], ISNUMBER( MATCH( tb_tela[id_tela], _xlfn._xlws.FILTER( tb_tela_prenda[id_tela], tb_tela_prenda[id_prenda]=Cotiz!L16 ), 0 ) ), "No necesario" )} -> No necesario | D31: {=_xlfn._xlws.FILTER( tb_color[color], ISNUMBER( MATCH( tb_color[id_color], _xlfn._xlws.FILTER( tb_tela_color[id_color], tb_tela_color[id_tela]=Cotiz!N9 ), 0 ) ),"No necesario" )} -> Amarillo | F31: {=_xlfn._xlws.FILTER( tb_marca[nombre_marca], tb_marca[id_prenda]=Cotiz!L16, "No necesario" )} -> No necesario | J31: S
D32: Anaranjado | H32: {=_xlfn._xlws.FILTER(tb_estilo[nombre_estilo], tb_estilo[id_prenda]=Cotiz!L14, "No necesario")} -> No necesario | J32: M
D33: Azul | J33: L
B34: {=_xlfn._xlws.FILTER( tb_tela[nombre_tela], ISNUMBER( MATCH( tb_tela[id_tela], _xlfn._xlws.FILTER( tb_tela_prenda[id_tela], tb_tela_prenda[id_prenda]=Cotiz!L17 ), 0 ) ), "No necesario" )} -> No necesario | D34: Blanco | F34: {=_xlfn._xlws.FILTER( tb_marca[nombre_marca], tb_marca[id_prenda]=Cotiz!L17, "No necesario" )} -> No necesario | J34: XL
D35: Celeste Bebé | J35: XXL
D36: Fucsia | H36: {=_xlfn._xlws.FILTER(tb_estilo[nombre_estilo], tb_estilo[id_prenda]=Cotiz!L15, "No necesario")} -> No necesario
B37: {=_xlfn._xlws.FILTER( tb_tela[nombre_tela], ISNUMBER( MATCH( tb_tela[id_tela], _xlfn._xlws.FILTER( tb_tela_prenda[id_tela], tb_tela_prenda[id_prenda]=Cotiz!L18 ), 0 ) ), "No necesario" )} -> No necesario | D37: Lila | F37: {=_xlfn._xlws.FILTER( tb_marca[nombre_marca], tb_marca[id_prenda]=Cotiz!L18, "No necesario" )} -> No necesario
D38: Negro
D39: Rojo
B40: {=_xlfn._xlws.FILTER( tb_tela[nombre_tela], ISNUMBER( MATCH( tb_tela[id_tela], _xlfn._xlws.FILTER( tb_tela_prenda[id_tela], tb_tela_prenda[id_prenda]=Cotiz!L19 ), 0 ) ), "No necesario" )} -> No necesario | D40: Rosado | F40: {=_xlfn._xlws.FILTER( tb_marca[nombre_marca], tb_marca[id_prenda]=Cotiz!L19, "No necesario" )} -> No necesario | H40: {=_xlfn._xlws.FILTER(tb_estilo[nombre_estilo], tb_estilo[id_prenda]=Cotiz!L16, "No necesario")} -> No necesario
D41: Turqueza
D42: Verde
B43: {=_xlfn._xlws.FILTER( tb_tela[nombre_tela], ISNUMBER( MATCH( tb_tela[id_tela], _xlfn._xlws.FILTER( tb_tela_prenda[id_tela], tb_tela_prenda[id_prenda]=Cotiz!L20 ), 0 ) ), "No necesario" )} -> No necesario | F43: {=_xlfn._xlws.FILTER( tb_marca[nombre_marca], tb_marca[id_prenda]=Cotiz!L20, "No necesario" )} -> No necesario | J43: {=IF( OR(Cotiz!L10=3,Cotiz!L10=4), _xlfn._xlws.FILTER( tb_talla[talla], ISNUMBER( MATCH( tb_talla[id_talla], _xlfn._xlws.FILTER( tb_talla_prenda[id_talla], tb_talla_prenda[id_prenda]=Cotiz!L10 ), 0 ) ), "No hay tallas" ), _xlfn._xlws.FILTER( tb_talla[talla], ISNUMBER( MATCH( tb_talla[id_talla], _xlfn._xlws.FILTER( tb_estilo_talla[id_talla], (tb_estilo_talla[id_prenda]=Cotiz!L10)* (tb_estilo_talla[id_estilo]=Cotiz!O10) ), 0 ) ), "No hay tallas" ) )} -> No hay tallas
H44: {=_xlfn._xlws.FILTER(tb_estilo[nombre_estilo], tb_estilo[id_prenda]=Cotiz!L17, "No necesario")} -> No necesario
...

Sheet Cotiz
U4: COTIZACIÓN
C6: Prenda | D6: Contexto | E6: Tela | F6: Color | G6: Estilo | H6: Talla | I6: Marca | J6: Cantidad | L6: Id_Prenda | M6: Id_Ctxto | N6: Id_Tela | O6: Id_Estilo | P6: Id_Talla | Q6: Id_Marca | R6: T x Prendas | S6: Id_Rango | V6: Descripción de producto | W6: Precio Unitario | X6: ADC. / DSCT. | Y6: Cantidad | Z6: Importe
C7: Polo | D7: Precio General | E7: Calidad intermedia | F7: Negro | G7: Recto | H7: L | I7: No necesario | J7: 2 | L7: =_xlfn.XLOOKUP(C7,tb_prenda[prenda],tb_prenda[id_prenda],"No encontrado") -> 1 | M7: =_xlfn.XLOOKUP(D7,tb_contexto_precio[nombre_contexto],tb_contexto_precio[id_contexto_precio],"No encontrado") -> 1 | N7: =_xlfn.XLOOKUP(E7,tb_tela[nombre_tela],tb_tela[id_tela],"No encontrado") -> 2 | O7: =_xlfn.XLOOKUP(G7,tb_estilo[nombre_estilo],tb_estilo[id_estilo],"No encontrado") -> 2 | P7: =_xlfn.XLOOKUP(H7,tb_talla[talla],tb_talla[id_talla],"No encontrado") -> 10 | Q7: =_xlfn.XLOOKUP(I7,tb_marca[nombre_marca],tb_marca[id_marca],"No encontrado") -> No encontrado | R7: =SUMIF($C$7:$C$11,C7,$J$7:$J$11) -> 5 | S7: =_xlfn.XLOOKUP(R7,tb_rango_cantidad[min],tb_rango_cantidad[id_rango],,-1) -> 1 | V7: =UPPER(IF(L7=1,C7&" de "&E7&" "&F7&" "&G7&" "&H7,IF(L7=2,C7&" de "&E7&" "&F7&" "&G7&" "&H7,IF(L7=3,C7&" "&F7&" TALLA "&H7,C7&" "&I7&" TALLA "&H7)))) -> POLO DE CALIDAD INTERMEDIA NEGRO RECTO L | W7: {=IF(L7=1, _xlfn.XLOOKUP(1, (tb_precio_polos[id_contexto_precio]=M7)* (tb_precio_polos[id_tela]=N7)* (tb_precio_polos[id_talla]=P7)* (tb_precio_polos[id_rango]=S7), tb_precio_polos[precio] ), IF(L7=2, _xlfn.XLOOKUP(1, (tb_precio_poleras[id_contexto_precio]=M7)* (tb_precio_poleras[id_tela]=N7)* (tb_precio_poleras[id_estilo]=O7)* (tb_precio_poleras[id_talla]=P7)* (tb_precio_poleras[id_rango]=S7), tb_precio_poleras[precio] ), IF(L7=3, _xlfn.XLOOKUP(1, (tb_precio_body[id_contexto_precio]=M7)* (tb_precio_body[id_talla]=P7)* (tb_precio_body[id_rango]=S7), tb_precio_body[precio] ), IF(L7=4, _xlfn.XLOOKUP(1, (tb_precio_boxer[id_contexto_precio]=M7)* (tb_precio_boxer[id_marca]=Q7)* (tb_precio_boxer[id_talla]=P7), tb_precio_boxer[precio] ), "" ))))} -> 28 | Y7: =J7 -> 2 | Z7: =(W7+X7)*Y7 -> 56
C8: Polo | D8: Precio General | E8: Alta calidad | F8: Blanco | G8: Recto | H8: M | I8: No necesario | J8: 2 | L8: =_xlfn.XLOOKUP(C8,tb_prenda[prenda],tb_prenda[id_prenda],"No encontrado") -> 1 | M8: =_xlfn.XLOOKUP(D8,tb_contexto_precio[nombre_contexto],tb_contexto_precio[id_contexto_precio],"No encontrado") -> 1 | N8: =_xlfn.XLOOKUP(E8,tb_tela[nombre_tela],tb_tela[id_tela],"No encontrado") -> 1 | O8: =_xlfn.XLOOKUP(G8,tb_estilo[nombre_estilo],tb_estilo[id_estilo],"No encontrado") -> 2 | P8: =_xlfn.XLOOKUP(H8,tb_talla[talla],tb_talla[id_talla],"No encontrado") -> 9 | Q8: =_xlfn.XLOOKUP(I8,tb_marca[nombre_marca],tb_marca[id_marca],"No encontrado") -> No encontrado | R8: =SUMIF($C$7:$C$11,C8,$J$7:$J$11) -> 5 | S8: =_xlfn.XLOOKUP(R8,tb_rango_cantidad[min],tb_rango_cantidad[id_rango],,-1) -> 1 | V8: =UPPER(IF(L8=1,C8&" de "&E8&" "&F8&" "&G8&" "&H8,IF(L8=2,C8&" de "&E8&" "&F8&" "&G8&" "&H8,IF(L8=3,C8&" "&F8&" TALLA "&H8,C8&" "&I8&" TALLA "&H8)))) -> POLO DE ALTA CALIDAD BLANCO RECTO M | W8: {=IF(L8=1, _xlfn.XLOOKUP(1, (tb_precio_polos[id_contexto_precio]=M8)* (tb_precio_polos[id_tela]=N8)* (tb_precio_polos[id_talla]=P8)* (tb_precio_polos[id_rango]=S8), tb_precio_polos[precio] ), IF(L8=2, _xlfn.XLOOKUP(1, (tb_precio_poleras[id_contexto_precio]=M8)* (tb_precio_poleras[id_tela]=N8)* (tb_precio_poleras[id_estilo]=O8)* (tb_precio_poleras[id_talla]=P8)* (tb_precio_poleras[id_rango]=S8), tb_precio_poleras[precio] ), IF(L8=3, _xlfn.XLOOKUP(1, (tb_precio_body[id_contexto_precio]=M8)* (tb_precio_body[id_talla]=P8)* (tb_precio_body[id_rango]=S8), tb_precio_body[precio] ), IF(L8=4, _xlfn.XLOOKUP(1, (tb_precio_boxer[id_contexto_precio]=M8)* (tb_precio_boxer[id_marca]=Q8)* (tb_precio_boxer[id_talla]=P8), tb_precio_boxer[precio] ), "" ))))} -> 35 | Y8: =J8 -> 2 | Z8: =(W8+X8)*Y8 -> 70
C9: Polo | D9: Precio General | E9: Alta calidad | F9: Azul | G9: Recto | H9: S | I9: No necesario | J9: 1 | L9: =_xlfn.XLOOKUP(C9,tb_prenda[prenda],tb_prenda[id_prenda],"No encontrado") -> 1 | M9: =_xlfn.XLOOKUP(D9,tb_contexto_precio[nombre_contexto],tb_contexto_precio[id_contexto_precio],"No encontrado") -> 1 | N9: =_xlfn.XLOOKUP(E9,tb_tela[nombre_tela],tb_tela[id_tela],"No encontrado") -> 1 | O9: =_xlfn.XLOOKUP(G9,tb_estilo[nombre_estilo],tb_estilo[id_estilo],"No encontrado") -> 2 | P9: =_xlfn.XLOOKUP(H9,tb_talla[talla],tb_talla[id_talla],"No encontrado") -> 8 | Q9: =_xlfn.XLOOKUP(I9,tb_marca[nombre_marca],tb_marca[id_marca],"No encontrado") -> No encontrado | R9: =SUMIF($C$7:$C$11,C9,$J$7:$J$11) -> 5 | S9: =_xlfn.XLOOKUP(R9,tb_rango_cantidad[min],tb_rango_cantidad[id_rango],,-1) -> 1 | V9: =UPPER(IF(L9=1,C9&" de "&E9&" "&F9&" "&G9&" "&H9,IF(L9=2,C9&" de "&E9&" "&F9&" "&G9&" "&H9,IF(L9=3,C9&" "&F9&" TALLA "&H9,C9&" "&I9&" TALLA "&H9)))) -> POLO DE ALTA CALIDAD AZUL RECTO S | W9: {=IF(L9=1, _xlfn.XLOOKUP(1, (tb_precio_polos[id_contexto_precio]=M9)* (tb_precio_polos[id_tela]=N9)* (tb_precio_polos[id_talla]=P9)* (tb_precio_polos[id_rango]=S9), tb_precio_polos[precio] ), IF(L9=2, _xlfn.XLOOKUP(1, (tb_precio_poleras[id_contexto_precio]=M9)* (tb_precio_poleras[id_tela]=N9)* (tb_precio_poleras[id_estilo]=O9)* (tb_precio_poleras[id_talla]=P9)* (tb_precio_poleras[id_rango]=S9), tb_precio_poleras[precio] ), IF(L9=3, _xlfn.XLOOKUP(1, (tb_precio_body[id_contexto_precio]=M9)* (tb_precio_body[id_talla]=P9)* (tb_precio_body[id_rango]=S9), tb_precio_body[precio] ), IF(L9=4, _xlfn.XLOOKUP(1, (tb_precio_boxer[id_contexto_precio]=M9)* (tb_precio_boxer[id_marca]=Q9)* (tb_precio_boxer[id_talla]=P9), tb_precio_boxer[precio] ), "" ))))} -> 35 | Y9: =J9 -> 1 | Z9: =(W9+X9)*Y9 -> 35
L10: =_xlfn.XLOOKUP(C10,tb_prenda[prenda],tb_prenda[id_prenda],"No encontrado") -> No encontrado | M10: =_xlfn.XLOOKUP(D10,tb_contexto_precio[nombre_contexto],tb_contexto_precio[id_contexto_precio],"No encontrado") -> No encontrado | N10: =_xlfn.XLOOKUP(E10,tb_tela[nombre_tela],tb_tela[id_tela],"No encontrado") -> No encontrado | O10: =_xlfn.XLOOKUP(G10,tb_estilo[nombre_estilo],tb_estilo[id_estilo],"No encontrado") -> No encontrado | P10: =_xlfn.XLOOKUP(H10,tb_talla[talla],tb_talla[id_talla],"No encontrado") -> No encontrado | Q10: =_xlfn.XLOOKUP(I10,tb_marca[nombre_marca],tb_marca[id_marca],"No encontrado") -> No encontrado | R10: =SUMIF($C$7:$C$11,C10,$J$7:$J$11) -> 0 | S10: =_xlfn.XLOOKUP(R10,tb_rango_cantidad[min],tb_rango_cantidad[id_rango],,-1) -> #N/A
L11: =_xlfn.XLOOKUP(C11,tb_prenda[prenda],tb_prenda[id_prenda],"No encontrado") -> No encontrado | M11: =_xlfn.XLOOKUP(D11,tb_contexto_precio[nombre_contexto],tb_contexto_precio[id_contexto_precio],"No encontrado") -> No encontrado | N11: =_xlfn.XLOOKUP(E11,tb_tela[nombre_tela],tb_tela[id_tela],"No encontrado") -> No encontrado | O11: =_xlfn.XLOOKUP(G11,tb_estilo[nombre_estilo],tb_estilo[id_estilo],"No encontrado") -> No encontrado | P11: =_xlfn.XLOOKUP(H11,tb_talla[talla],tb_talla[id_talla],"No encontrado") -> No encontrado | Q11: =_xlfn.XLOOKUP(I11,tb_marca[nombre_marca],tb_marca[id_marca],"No encontrado") -> No encontrado | R11: =SUMIF($C$7:$C$11,C11,$J$7:$J$11) -> 0 | S11: =_xlfn.XLOOKUP(R11,tb_rango_cantidad[min],tb_rango_cantidad[id_rango],,-1) -> #N/A
L12: =_xlfn.XLOOKUP(C12,tb_prenda[prenda],tb_prenda[id_prenda],"No encontrado") -> No encontrado | M12: =_xlfn.XLOOKUP(D12,tb_contexto_precio[nombre_contexto],tb_contexto_precio[id_contexto_precio],"No encontrado") -> No encontrado | N12: =_xlfn.XLOOKUP(E12,tb_tela[nombre_tela],tb_tela[id_tela],"No encontrado") -> No encontrado | O12: =_xlfn.XLOOKUP(G12,tb_estilo[nombre_estilo],tb_estilo[id_estilo],"No encontrado") -> No encontrado | P12: =_xlfn.XLOOKUP(H12,tb_talla[talla],tb_talla[id_talla],"No encontrado") -> No encontrado | Q12: =_xlfn.XLOOKUP(I12,tb_marca[nombre_marca],tb_marca[id_marca],"No encontrado") -> No encontrado | R12: =SUMIF($C$7:$C$11,C12,$J$7:$J$11) -> 0 | S12: =_xlfn.XLOOKUP(R12,tb_rango_cantidad[min],tb_rango_cantidad[id_rango],,-1) -> #N/A
L13: =_xlfn.XLOOKUP(C13,tb_prenda[prenda],tb_prenda[id_prenda],"No encontrado") -> No encontrado | M13: =_xlfn.XLOOKUP(D13,tb_contexto_precio[nombre_contexto],tb_contexto_precio[id_contexto_precio],"No encontrado") -> No encontrado | N13: =_xlfn.XLOOKUP(E13,tb_tela[nombre_tela],tb_tela[id_tela],"No encontrado") -> No encontrado | O13: =_xlfn.XLOOKUP(G13,tb_estilo[nombre_estilo],tb_estilo[id_estilo],"No encontrado") -> No encontrado | P13: =_xlfn.XLOOKUP(H13,tb_talla[talla],tb_talla[id_talla],"No encontrado") -> No encontrado | Q13: =_xlfn.XLOOKUP(I13,tb_marca[nombre_marca],tb_marca[id_marca],"No encontrado") -> No encontrado | R13: =SUMIF($C$7:$C$11,C13,$J$7:$J$11) -> 0 | S13: =_xlfn.XLOOKUP(R13,tb_rango_cantidad[min],tb_rango_cantidad[id_rango],,-1) -> #N/A
L14: =_xlfn.XLOOKUP(C14,tb_prenda[prenda],tb_prenda[id_prenda],"No encontrado") -> No encontrado | M14: =_xlfn.XLOOKUP(D14,tb_contexto_precio[nombre_contexto],tb_contexto_precio[id_contexto_precio],"No encontrado") -> No encontrado | N14: =_xlfn.XLOOKUP(E14,tb_tela[nombre_tela],tb_tela[id_tela],"No encontrado") -> No encontrado | O14: =_xlfn.XLOOKUP(G14,tb_estilo[nombre_estilo],tb_estilo[id_estilo],"No encontrado") -> No encontrado | P14: =_xlfn.XLOOKUP(H14,tb_talla[talla],tb_talla[id_talla],"No encontrado") -> No encontrado | Q14: =_xlfn.XLOOKUP(I14,tb_marca[nombre_marca],tb_marca[id_marca],"No encontrado") -> No encontrado | R14: =SUMIF($C$7:$C$11,C14,$J$7:$J$11) -> 0 | S14: =_xlfn.XLOOKUP(R14,tb_rango_cantidad[min],tb_rango_cantidad[id_rango],,-1) -> #N/A
L15: =_xlfn.XLOOKUP(C15,tb_prenda[prenda],tb_prenda[id_prenda],"No encontrado") -> No encontrado | M15: =_xlfn.XLOOKUP(D15,tb_contexto_precio[nombre_contexto],tb_contexto_precio[id_contexto_precio],"No encontrado") -> No encontrado | N15: =_xlfn.XLOOKUP(E15,tb_tela[nombre_tela],tb_tela[id_tela],"No encontrado") -> No encontrado | O15: =_xlfn.XLOOKUP(G15,tb_estilo[nombre_estilo],tb_estilo[id_estilo],"No encontrado") -> No encontrado | P15: =_xlfn.XLOOKUP(H15,tb_talla[talla],tb_talla[id_talla],"No encontrado") -> No encontrado | Q15: =_xlfn.XLOOKUP(I15,tb_marca[nombre_marca],tb_marca[id_marca],"No encontrado") -> No encontrado | R15: =SUMIF($C$7:$C$11,C15,$J$7:$J$11) -> 0 | S15: =_xlfn.XLOOKUP(R15,tb_rango_cantidad[min],tb_rango_cantidad[id_rango],,-1) -> #N/A
L16: =_xlfn.XLOOKUP(C16,tb_prenda[prenda],tb_prenda[id_prenda],"No encontrado") -> No encontrado | M16: =_xlfn.XLOOKUP(D16,tb_contexto_precio[nombre_contexto],tb_contexto_precio[id_contexto_precio],"No encontrado") -> No encontrado | N16: =_xlfn.XLOOKUP(E16,tb_tela[nombre_tela],tb_tela[id_tela],"No encontrado") -> No encontrado | O16: =_xlfn.XLOOKUP(G16,tb_estilo[nombre_estilo],tb_estilo[id_estilo],"No encontrado") -> No encontrado | P16: =_xlfn.XLOOKUP(H16,tb_talla[talla],tb_talla[id_talla],"No encontrado") -> No encontrado | Q16: =_xlfn.XLOOKUP(I16,tb_marca[nombre_marca],tb_marca[id_marca],"No encontrado") -> No encontrado | R16: =SUMIF($C$7:$C$11,C16,$J$7:$J$11) -> 0 | S16: =_xlfn.XLOOKUP(R16,tb_rango_cantidad[min],tb_rango_cantidad[id_rango],,-1) -> #N/A
L17: =_xlfn.XLOOKUP(C17,tb_prenda[prenda],tb_prenda[id_prenda],"No encontrado") -> No encontrado | M17: =_xlfn.XLOOKUP(D17,tb_contexto_precio[nombre_contexto],tb_contexto_precio[id_contexto_precio],"No encontrado") -> No encontrado | N17: =_xlfn.XLOOKUP(E17,tb_tela[nombre_tela],tb_tela[id_tela],"No encontrado") -> No encontrado | O17: =_xlfn.XLOOKUP(G17,tb_estilo[nombre_estilo],tb_estilo[id_estilo],"No encontrado") -> No encontrado | P17: =_xlfn.XLOOKUP(H17,tb_talla[talla],tb_talla[id_talla],"No encontrado") -> No encontrado | Q17: =_xlfn.XLOOKUP(I17,tb_marca[nombre_marca],tb_marca[id_marca],"No encontrado") -> No encontrado | R17: =SUMIF($C$7:$C$11,C17,$J$7:$J$11) -> 0 | S17: =_xlfn.XLOOKUP(R17,tb_rango_cantidad[min],tb_rango_cantidad[id_rango],,-1) -> #N/A
L18: =_xlfn.XLOOKUP(C18,tb_prenda[prenda],tb_prenda[id_prenda],"No encontrado") -> No encontrado | M18: =_xlfn.XLOOKUP(D18,tb_contexto_precio[nombre_contexto],tb_contexto_precio[id_contexto_precio],"No encontrado") -> No encontrado | N18: =_xlfn.XLOOKUP(E18,tb_tela[nombre_tela],tb_tela[id_tela],"No encontrado") -> No encontrado | O18: =_xlfn.XLOOKUP(G18,tb_estilo[nombre_estilo],tb_estilo[id_estilo],"No encontrado") -> No encontrado | P18: =_xlfn.XLOOKUP(H18,tb_talla[talla],tb_talla[id_talla],"No encontrado") -> No encontrado | Q18: =_xlfn.XLOOKUP(I18,tb_marca[nombre_marca],tb_marca[id_marca],"No encontrado") -> No encontrado | R18: =SUMIF($C$7:$C$11,C18,$J$7:$J$11) -> 0 | S18: =_xlfn.XLOOKUP(R18,tb_rango_cantidad[min],tb_rango_cantidad[id_rango],,-1) -> #N/A
L19: =_xlfn.XLOOKUP(C19,tb_prenda[prenda],tb_prenda[id_prenda],"No encontrado") -> No encontrado | M19: =_xlfn.XLOOKUP(D19,tb_contexto_precio[nombre_contexto],tb_contexto_precio[id_contexto_precio],"No encontrado") -> No encontrado | N19: =_xlfn.XLOOKUP(E19,tb_tela[nombre_tela],tb_tela[id_tela],"No encontrado") -> No encontrado | O19: =_xlfn.XLOOKUP(G19,tb_estilo[nombre_estilo],tb_estilo[id_estilo],"No encontrado") -> No encontrado | P19: =_xlfn.XLOOKUP(H19,tb_talla[talla],tb_talla[id_talla],"No encontrado") -> No encontrado | Q19: =_xlfn.XLOOKUP(I19,tb_marca[nombre_marca],tb_marca[id_marca],"No encontrado") -> No encontrado | R19: =SUMIF($C$7:$C$11,C19,$J$7:$J$11) -> 0 | S19: =_xlfn.XLOOKUP(R19,tb_rango_cantidad[min],tb_rango_cantidad[id_rango],,-1) -> #N/A
L20: =_xlfn.XLOOKUP(C20,tb_prenda[prenda],tb_prenda[id_prenda],"No encontrado") -> No encontrado | M20: =_xlfn.XLOOKUP(D20,tb_contexto_precio[nombre_contexto],tb_contexto_precio[id_contexto_precio],"No encontrado") -> No encontrado | N20: =_xlfn.XLOOKUP(E20,tb_tela[nombre_tela],tb_tela[id_tela],"No encontrado") -> No encontrado | O20: =_xlfn.XLOOKUP(G20,tb_estilo[nombre_estilo],tb_estilo[id_estilo],"No encontrado") -> No encontrado | P20: =_xlfn.XLOOKUP(H20,tb_talla[talla],tb_talla[id_talla],"No encontrado") -> No encontrado | Q20: =_xlfn.XLOOKUP(I20,tb_marca[nombre_marca],tb_marca[id_marca],"No encontrado") -> No encontrado | R20: =SUMIF($C$7:$C$11,C20,$J$7:$J$11) -> 0 | S20: =_xlfn.XLOOKUP(R20,tb_rango_cantidad[min],tb_rango_cantidad[id_rango],,-1) -> #N/A
L21: =_xlfn.XLOOKUP(C21,tb_prenda[prenda],tb_prenda[id_prenda],"No encontrado") -> No encontrado | M21: =_xlfn.XLOOKUP(D21,tb_contexto_precio[nombre_contexto],tb_contexto_precio[id_contexto_precio],"No encontrado") -> No encontrado | N21: =_xlfn.XLOOKUP(E21,tb_tela[nombre_tela],tb_tela[id_tela],"No encontrado") -> No encontrado | O21: =_xlfn.XLOOKUP(G21,tb_estilo[nombre_estilo],tb_estilo[id_estilo],"No encontrado") -> No encontrado | P21: =_xlfn.XLOOKUP(H21,tb_talla[talla],tb_talla[id_talla],"No encontrado") -> No encontrado | Q21: =_xlfn.XLOOKUP(I21,tb_marca[nombre_marca],tb_marca[id_marca],"No encontrado") -> No encontrado | R21: =SUMIF($C$7:$C$11,C21,$J$7:$J$11) -> 0 | S21: =_xlfn.XLOOKUP(R21,tb_rango_cantidad[min],tb_rango_cantidad[id_rango],,-1) -> #N/A
... L26: =_xlfn.XLOOKUP(C26,tb_prenda[prenda],tb_prenda[id_prenda],"No encontrado") -> No encontrado | M26: =_xlfn.XLOOKUP(D26,tb_contexto_precio[nombre_contexto],tb_contexto_precio[id_contexto_precio],"No encontrado") -> No encontrado | N26: =_xlfn.XLOOKUP(E26,tb_tela[nombre_tela],tb_tela[id_tela],"No encontrado") -> No encontrado | O26: =_xlfn.XLOOKUP(G26,tb_estilo[nombre_estilo],tb_estilo[id_estilo],"No encontrado") -> No encontrado | P26: =_xlfn.XLOOKUP(H26,tb_talla[talla],tb_talla[id_talla],"No encontrado") -> No encontrado | Q26: =_xlfn.XLOOKUP(I26,tb_marca[nombre_marca],tb_marca[id_marca],"No encontrado") -> No encontrado | R26: =SUMIF($C$7:$C$11,C26,$J$7:$J$11) -> 0 | S26: =_xlfn.XLOOKUP(R26,tb_rango_cantidad[min],tb_rango_cantidad[id_rango],,-1) -> #N/A
Y27: Total | Z27: =SUM(Z7:Z11) -> 161

Sheet Pedidos
B2: ID | C2: Referencia Cliente | D2: Telefono | E2: Fecha de registro | F2: Destino | G2: Total | H2: Pago | I2: Debe | J2: Fecha de envío | K2: Diseño | L2: Comanda | M2: Canceló | N2: Video | O2: Guía - Delivery | P2: Enviado
B3: 1 | C3: ANONIMO | D3: 980 963 420 | E3: 45799 | F3: DELIVERY | G3: 326 | H3: 163 | I3: 163 | J3: 45803 | M3: FALSE | N3: FALSE | O3: FALSE | P3: TRUE
B4: 2 | C4: ANONIMO | D4: 918 385 078 | E4: 45799 | F4: PROVINCIA | G4: 176 | H4: 88 | I4: 88 | J4: 45803 | L4: FALSE | M4: FALSE | N4: FALSE | O4: FALSE | P4: TRUE
B5: 3 | C5: ANONIMO | D5: 995 429 177 | E5: 45799 | F5: DELIVERY | G5: 288 | H5: 150 | I5: 138 | J5: 45801 | M5: FALSE | N5: FALSE | O5: FALSE | P5: TRUE
B6: 4 | C6: ANONIMO | D6: 912 939 988 | E6: 45799 | F6: DELIVERY | G6: 318 | H6: 150 | I6: 168 | J6: 45803 | M6: FALSE | N6: FALSE | O6: FALSE | P6: TRUE
B7: 5 | C7: ANONIMO | D7: 940 529 281 | E7: 45799 | F7: DELIVERY | G7: 130 | H7: 65 | I7: 65 | J7: 45803 | M7: FALSE | N7: FALSE | O7: FALSE | P7: TRUE
B8: 6 | C8: ANONIMO | D8: 951 538 225 | E8: 45799 | F8: PROVINCIA | G8: 264 | H8: 132 | I8: 132 | J8: 45801 | L8: FALSE | M8: FALSE | N8: FALSE | O8: FALSE | P8: TRUE
B9: 7 | C9: ANONIMO | D9: 959 583 783 | E9: 45799 | F9: DELIVERY | G9: 54 | H9: 30 | I9: 24 | J9: 45801 | M9: FALSE | N9: FALSE | O9: FALSE | P9: TRUE
B10: 8 | C10: ANONIMO | D10: 917 235 054 | E10: 45801 | F10: PROVINCIA | G10: 175 | H10: 90 | I10: 85 | J10: 45804 | L10: FALSE | M10: FALSE | N10: FALSE | O10: FALSE | P10: TRUE
B11: 9 | C11: ANONIMO | D11: 999 902 915 | E11: 45801 | F11: PROVINCIA | G11: 270 | H11: 130 | I11: 140 | J11: 45804 | L11: FALSE | M11: FALSE | N11: FALSE | O11: FALSE | P11: TRUE
B12: 10 | C12: ANONIMO | D12: 929 494 707 | E12: 45801 | F12: PROVINCIA | G12: 418 | H12: 200 | I12: 218 | J12: 45804 | L12: FALSE | M12: FALSE | N12: FALSE | O12: FALSE | P12: TRUE
B13: 11 | C13: ANONIMO | D13: 921 897 237 | E13: 45801 | F13: PROVINCIA | G13: 90 | H13: 90 | I13: 0 | J13: 45826 | L13: FALSE | M13: FALSE | N13: FALSE | O13: FALSE | P13: TRUE
B14: 12 | C14: ANONIMO | D14: 929 477 913 | E14: 45801 | F14: DELIVERY | G14: 108 | H14: 54 | I14: 54 | J14: 45802 | M14: FALSE | N14: FALSE | O14: FALSE | P14: TRUE
B15: 13 | C15: ANONIMO | D15: 978 430 461 | E15: 45801 | F15: DELIVERY | G15: 180 | H15: 90 | I15: 90 | J15: 45805 | M15: FALSE | N15: FALSE | O15: FALSE | P15: TRUE
B16: 14 | C16: ANONIMO | D16: 983 806 545 | E16: 45803 | F16: PROVINCIA | G16: 199 | H16: 80 | I16: 119 | J16: 45810 | L16: FALSE | M16: FALSE | N16: FALSE | O16: FALSE | P16: TRUE
B17: 15 | C17: ANONIMO | D17: 986 475 756 | E17: 45804 | F17: DELIVERY | G17: 25 | H17: 13 | I17: 12 | J17: 45806 | M17: FALSE | N17: FALSE | O17: FALSE | P17: TRUE
B18: 16 | C18: ANONIMO | D18: 974 221 993 | E18: 45804 | F18: DELIVERY | G18: 290 | H18: 150 | I18: 140 | J18: 45813 | M18: FALSE | N18: FALSE | O18: FALSE | P18: TRUE
B19: 17 | C19: ANONIMO | D19: 955 827 527 | E19: 45804 | F19: DELIVERY | G19: 382 | H19: 165 | I19: 217 | J19: 45806 | M19: FALSE | N19: FALSE | O19: FALSE | P19: TRUE
B20: 18 | C20: ANONIMO | D20: 943 947 485 | E20: 45804 | F20: DELIVERY | G20: 61 | H20: 30 | I20: 31 | J20: 45807 | M20: FALSE | N20: FALSE | O20: FALSE | P20: TRUE
B21: 19 | C21: ANONIMO | D21: 926 707 381 | E21: 45806 | F21: DELIVERY | G21: 25 | H21: 15 | I21: 10 | J21: 45813 | M21: FALSE | N21: FALSE | O21: FALSE | P21: TRUE
B22: 20 | C22: ANONIMO | D22: 930 292 012 | E22: 45806 | F22: PROVINCIA | G22: 66 | H22: 33 | I22: 33 | J22: 45813 | L22: FALSE | M22: FALSE | N22: FALSE | O22: FALSE | P22: TRUE
B23: 21 | C23: ANONIMO | D23: 940 193 532 | E23: 45807 | F23: DELIVERY | G23: 159 | H23: 80 | I23: 79 | J23: 45814 | M23: FALSE | N23: FALSE | O23: FALSE | P23: TRUE
B24: 22 | C24: ANONIMO | D24: 992 799 295 | E24: 45807 | F24: PROVINCIA | G24: 55 | H24: 30 | I24: 25 | J24: 45815 | L24: FALSE | M24: FALSE | N24: FALSE | O24: FALSE | P24: TRUE
B25: 23 | C25: ONLY YOU FREID | D25: 970 298 577 | E25: 45808 | F25: DELIVERY | G25: 41 | H25: 20 | I25: 21 | J25: 45812 | M25: FALSE | N25: FALSE | O25: FALSE | P25: TRUE
B26: 24 | C26: CUMPLE CORBATA | D26: 993 381 136 | E26: 45809 | F26: DELIVERY | G26: 94 | H26: 50 | I26: 44 | J26: 45814 | M26: FALSE | N26: FALSE | O26: FALSE | P26: TRUE
B27: 25 | C27: GRAD PRIMER DISTINTO | D27: 976314252 | E27: 45810 | F27: DELIVERY | G27: 26 | H27: 13 | I27: 13 | J27: 45813 | M27: FALSE | N27: FALSE | O27: FALSE | P27: TRUE
B28: 26 | C28: TRI POLO Y BODY | D28: 965 951 068 | E28: 45810 | F28: PROVINCIA | G28: 75 | H28: 37.5 | I28: 37.5 | J28: 45817 | L28: FALSE | M28: FALSE | N28: FALSE | O28: FALSE | P28: TRUE
B29: 27 | C29: MISS ANTES SERÁ | D29: 960 550 912 | E29: 45811 | F29: DELIVERY | G29: 150 | H29: 75 | I29: 75 | J29: 45818 | M29: FALSE | N29: FALSE | O29: FALSE | P29: TRUE
B30: 28 | C30: MAESTRAS X6 | D30: 986 158 202 | E30: 45811 | F30: PROVINCIA | G30: 150 | H30: 75 | I30: 75 | J30: 45815 | L30: FALSE | M30: FALSE | N30: FALSE | O30: FALSE | P30: TRUE
B31: 29 | C31: PAPA NINFA | D31: 912 409 112 | E31: 45811 | F31: PROVINCIA | G31: 65 | H31: 30 | I31: 35 | J31: 45815 | L31: FALSE | M31: FALSE | N31: FALSE | O31: FALSE | P31: TRUE
B32: 30 | C32: PLIM PLIM ROJO FAM | D32: 998 962 622 | E32: 45812 | F32: PROVINCIA | G32: 309 | H32: 150 | I32: 159 | J32: 45819 | L32: FALSE | M32: FALSE | N32: FALSE | O32: FALSE | P32: TRUE
B33: 31 | C33: PAPA ZENON A3 | D33: 916 729 244 | E33: 45812 | F33: RECOJO | G33: 105 | H33: 50 | I33: 55 | J33: 45819 | M33: FALSE | N33: FALSE | O33: FALSE | P33: TRUE
B34: 32 | C34: POCOYO SE CREE HABIL | D34: 963 692 931 | E34: 45812 | F34: DELIVERY | G34: 103 | H34: 50 | I34: 53 | J34: 45814 | M34: FALSE | N34: FALSE | O34: FALSE | P34: TRUE
B35: 33 | C35: LEONES PARTE 2 | D35: 959 059 773 | E35: 45812 | F35: PROVINCIA | G35: 366 | H35: 172 | I35: 194 | J35: 45819 | L35: FALSE | M35: FALSE | N35: FALSE | O35: FALSE | P35: TRUE
B36: 34 | C36: PAPA WEN | D36: 935 824 464 | E36: 45813 | F36: PROVINCIA | G36: 298 | H36: 138 | I36: 160 | J36: 45817 | L36: FALSE | M36: FALSE | N36: FALSE | O36: FALSE | P36: TRUE
B37: 35 | C37: GRAD Y PAPÁ | D37: 931 396 806 | E37: 45813 | F37: PROVINCIA | G37: 503 | H37: 250 | I37: 253 | J37: 45818 | L37: FALSE | M37: FALSE | N37: FALSE | O37: FALSE | P37: TRUE
B38: 36 | C38: PAPA TRI HUAYCAN | D38: 925 546 481 | E38: 45813 | F38: SHALOM-LIMA | G38: 95 | H38: 50 | I38: 45 | J38: 45819 | L38: FALSE | M38: FALSE | N38: FALSE | O38: FALSE | P38: TRUE
B39: 37 | C39: PAPA PUÑO ALAS | D39: 965 300 158 | E39: 45813 | F39: PROVINCIA | G39: 60 | H39: 30 | I39: 30 | J39: 45819 | L39: FALSE | M39: FALSE | N39: FALSE | O39: FALSE | P39: TRUE
B40: 38 | C40: BOB ESPONJA | D40: 947 658 094 | E40: 45813 | F40: PROVINCIA | G40: 189 | H40: 80 | I40: 109 | J40: 45819 | L40: FALSE | M40: FALSE | N40: FALSE | O40: FALSE | P40: TRUE
B41: 39 | C41: LA MEJOR MAMÁ | D41: 964 877 388 | E41: 45814 | F41: DELIVERY | G41: 30 | H41: 15 | I41: 15 | J41: 45819 | M41: FALSE | N41: FALSE | O41: FALSE | P41: TRUE
...

Sheet Det. Ped.
B1: id_pedido | C1: Prenda | D1: Contexto | E1: Tela | F1: Color | G1: Estilo | H1: Talla | I1: Marca | J1: Cantidad
B2: 1 | C2: Polo | D2: Día de la Educación Inicial | E2: Alta Calidad | F2: Negro | G2: Niño | H2: T6 | J2: 1
B3: 1 | C3: Polo | D3: Día de la Educación Inicial | E3: Alta Calidad | F3: Blanco | G3: Princesa | H3: S | J3: 1
B4: 1 | C4: Polo | D4: Día de la Educación Inicial | E4: Alta Calidad | F4: Blanco | G4: Princesa | H4: M | J4: 12
B5: 1 | C5: Polo | D5: Día de la Educación Inicial | E5: Alta Calidad | F5: Blanco | G5: Princesa | H5: L | J5: 1
B6: 1 | C6: Polo | D6: Día de la Educación Inicial | E6: Alta Calidad | F6: Blanco | G6: Recto | H6: L | J6: 1
B7: 2 | C7: Polo | D7: Día de la Educación Inicial | E7: Alta Calidad | F7: Fucsia | G7: Princesa | H7: M | J7: 2
B8: 2 | C8: Polo | D8: Día de la Educación Inicial | E8: Alta Calidad | F8: Fucsia | G8: Princesa | H8: L | J8: 2
B9: 2 | C9: Polo | D9: Día de la Educación Inicial | E9: Alta Calidad | F9: Turqueza | G9: Princesa | H9: S | J9: 1
B10: 2 | C10: Polo | D10: Día de la Educación Inicial | E10: Alta Calidad | F10: Lila | G10: Princesa | H10: M | J10: 1
B11: 2 | C11: Polo | D11: Día de la Educación Inicial | E11: Alta Calidad | F11: Negro | G11: Princesa | H11: M | J11: 1
B12: 3 | C12: Polo | D12: Precio General | E12: Alta Calidad | F12: Blanco | G12: Princesa | H12: S | J12: 2
B13: 3 | C13: Polo | D13: Precio General | E13: Alta Calidad | F13: Blanco | G13: Princesa | H13: M | J13: 1
... B65: 18 | C65: Polo | D65: Precio Precio General | E65: Alta Calidad | F65: Negro | G65: Niño | H65: T2 | J65: 1
B66: 18 | C66: Body | D66: Precio General | E66: Alta Calidad | F66: Negro | H66: 8 - 11 m | J66: 1
B67: 19 | C67: Polo | D67: Día del Padre | E67: Calidad Intermedia | F67: Negro | G67: Recto | H67: M | J67: 1
B68: 20 | C68: Polo | D68: Día de la Educación Inicial | E68: Alta Calidad | F68: Negro | G68: Princesa | H68: M | J68: 2
B69: 20 | C69: Polo | D69: Día de la Educación Inicial | E69: Alta Calidad | F69: Rojo | G69: Princesa | H69: M | J69: 1
B70: 21 | C70: Polo | D70: Día de la Madre | E70: Alta Calidad | F70: Blanco | G70: Niño | H70: T8 | J70: 1
B71: 21 | C71: Polo | D71: Día de la Madre | E71: Alta Calidad | F71: Rojo | G71: Niño | H71: T10 | J71: 1
B72: 21 | C72: Polo | D72: Día de la Madre | E72: Alta Calidad | F72: Negro | G72: Princesa | H72: M | J72: 2
B73: 21 | C73: Polo | D73: Día de la Madre | E73: Alta Calidad | F73: Rojo | G73: Princesa | H73: L | J73: 1
B74: 21 | C74: Polo | D74: Precio General | E74: Alta Calidad | F74: Blanco | G74: Niño | H74: T10 | J74: 1
B75: 22 | C75: Polo | D75: Día del Padre | E75: Alta Calidad | F75: Negro | G75: Recto | H75: L | J75: 1
B76: 22 | C76: Body | D76: Día del Padre | E76: Alta Calidad | F76: Negro | H76: 0 - 3 m | J76: 1
B77: 23 | C77: Polo | D77: Precio General | E77: Alta Calidad | F77: Negro | G77: Recto | H77: M | J77: 1
B78: 24 | C78: Polo | D78: Cumpleaños | E78: Calidad Intermedia | F78: Negro | G78: Recto | H78: T2 | J78: 1
B79: 24 | C79: Polo | D79: Cumpleaños | E79: Calidad Intermedia | F79: Negro | G79: Recto | H79: S | J79: 1
B80: 24 | C80: Polo | D80: Cumpleaños | E80: Calidad Intermedia | F80: Negro | G80: Recto | H80: L | J80: 1
B81: 25 | C81: Polo | D81: Graduación | E81: Alta Calidad | F81: Blanco | G81: Niño | H81: T6 | J81: 1
B82: 26 | C82: Polo | D82: Día del Padre | E82: Calidad Intermedia | F82: Blanco | G82: Recto | H82: L | J82: 2
B83: 26 | C83: Body | D83: Día del Padre | E83: Alta Calidad | F83: Blanco | H83: 8 - 11 m | J83: 1
B84: 27 | C84: Polo | D84: Maestras | E84: Alta Calidad | F84: Lila | G84: Princesa | H84: L | J84: 1
B85: 27 | C85: Polo | D85: Maestras | E85: Alta Calidad | F85: Fucsia | G85: Princesa | H85: L | J85: 1
B86: 27 | C86: Polo | D86: Maestras | E86: Alta Calidad | F86: Blanco | G86: Princesa | H86: L | J86: 2
B87: 27 | C87: Polo | D87: Maestras | E87: Alta Calidad | F87: Negro | G87: Princesa | H87: L | J87: 2
B88: 28 | C88: Polo | D88: Maestras | E88: Alta Calidad | F88: Rosado | G88: Princesa | H88: L | J88: 2
B89: 28 | C89: Polo | D89: Maestras | E89: Alta Calidad | F89: Turqueza | G89: Princesa | H89: L | J89: 2
B90: 28 | C90: Polo | D90: Maestras | E90: Alta Calidad | F90: Blanco | G90: Princesa | H90: L | J90: 2
B91: 29 | C91: Polo | D91: Día del Padre | E91: Alta Calidad | F91: Blanco | G91: Recto | H91: L | J91: 2
...
